Workbook

Sheet Config
A1: =IF(Config!$B$3="FR","Q17-Mini — Compatibilité MOSFET & R14/R15 initiales — Configuration","Q17-Mini — MOSFET Compatibility & Initial R14/R15 — Configuration") -> Q17-Mini — MOSFET Compatibility & Initial R14/R15 — Configuration
A2: =IF(Config!$B$3="FR","Modifier uniquement les cellules jaunes. Les valeurs R14/R15 calculées sont des valeurs initiales à valider à l’oscilloscope.","Edit yellow cells only. Calculated R14/R15 values are initial values to validate on the oscilloscope.") -> Edit yellow cells only. Calculated R14/R15 values are initial values to validate on the oscilloscope.
A3: =IF(Config!$B$3="FR","Langue","Language") -> Language | B3: EN | D3: FR / EN
A4: =IF(Config!$B$3="FR","Paramètre","Parameter") -> Parameter | B4: =IF(Config!$B$3="FR","Valeur","Value") -> Value | C4: =IF(Config!$B$3="FR","Unité","Unit") -> Unit | D4: =IF(Config!$B$3="FR","Remarque","Note") -> Note
A5: =IF(Config!$B$3="FR","Version","Version") -> Version | B5: 1.1b35 | D5: =IF(Config!$B$3="FR","Version bilingue FR/EN — mécanisme direct sans feuille supplémentaire","FR/EN bilingual version — direct mechanism without extra sheet") -> FR/EN bilingual version — direct mechanism without extra sheet
A6: =IF(Config!$B$3="FR","Date","Date") -> Date | B6: 08/10/2026
A8: =IF(Config!$B$3="FR","Résistance de référence","Reference resistor") -> Reference resistor | B8: R14 | D8: =IF(Config!$B$3="FR","R14 ou R15","R14 or R15") -> R14 or R15
A9: =IF(Config!$B$3="FR","Valeur initiale cible","Initial target value") -> Initial target value | B9: 100 | C9: Ω | D9: =IF(Config!$B$3="FR","Point de départ uniquement","Starting point only") -> Starting point only
A11: =IF(Config!$B$3="FR","Rail |V|","Rail |V|") -> Rail |V| | B11: 50 | C11: V
A12: =IF(Config!$B$3="FR","Charge RL","Load RL") -> Load RL | B12: 8 | C12: Ω
A13: =IF(Config!$B$3="FR","Id de calcul","Calculation Id") -> Calculation Id | B13: 3.125 | C13: A
A14: =IF(Config!$B$3="FR","Boucle de grille Lloop","Gate loop Lloop") -> Gate loop Lloop | B14: 30 | C14: nH
A15: =IF(Config!$B$3="FR","Rdriver HF","HF Rdriver") -> HF Rdriver | B15: 0 | C15: Ω
A16: =IF(Config!$B$3="FR","Marge de stabilité","Stability margin") -> Stability margin | B16: 1.4
A17: =IF(Config!$B$3="FR","Marge Vdss","Vdss margin") -> Vdss margin | B17: 1.2 | D17: =IF(Config!$B$3="FR","Critère : |Vdss| ≥ 2 × rail × marge","Criterion: |Vdss| ≥ 2 × rail × margin") -> Criterion: |Vdss| ≥ 2 × rail × margin
A18: =IF(Config!$B$3="FR","Marge Id","Id margin") -> Id margin | B18: 1.5 | D18: =IF(Config!$B$3="FR","Critère : Idmax ≥ Id calcul × marge","Criterion: Idmax ≥ calculation Id × margin") -> Criterion: Idmax ≥ calculation Id × margin
A19: =IF(Config!$B$3="FR","Écart N/P max","Max N/P mismatch") -> Max N/P mismatch | B19: 0.15 | D19: =IF(Config!$B$3="FR","Rapport relatif","Relative ratio") -> Relative ratio
A20: =IF(Config!$B$3="FR","Fréquence HF à préserver","HF frequency to preserve") -> HF frequency to preserve | B20: 100 | C20: kHz
A21: =IF(Config!$B$3="FR","Déphasage grille max","Max gate phase shift") -> Max gate phase shift | B21: 5 | C21: °
A22: =IF(Config!$B$3="FR","Perte grille max","Max gate loss") -> Max gate loss | B22: 0.1 | C22: dB
A23: =IF(Config!$B$3="FR","Ciss max","Max Ciss") -> Max Ciss | B23: 3500 | C23: pF
A24: =IF(Config!$B$3="FR","COMPATIBILITÉ DE PAIRE CURRENT-DUMPER","CURRENT-DUMPER PAIR COMPATIBILITY") -> CURRENT-DUMPER PAIR COMPATIBILITY
A25: =IF(Config!$B$3="FR","Poids profil Ceff","Ceff profile weight") -> Ceff profile weight | B25: 0.3 | D25: =IF(Config!$B$3="FR","Similitude N/P de Ceff dans plusieurs états du follower.","N/P Ceff similarity across several follower states.") -> N/P Ceff similarity across several follower states.
A26: =IF(Config!$B$3="FR","Poids similitude Qgd","Qgd similarity weight") -> Qgd similarity weight | B26: 0.2 | D26: =IF(Config!$B$3="FR","Charge de plateau Miller / transition.","Miller plateau / transition charge.") -> Miller plateau / transition charge.
A27: =IF(Config!$B$3="FR","Poids similitude Qg","Qg similarity weight") -> Qg similarity weight | B27: 0.15 | D27: =IF(Config!$B$3="FR","Charge de grille totale.","Total gate charge.") -> Total gate charge.
A28: =IF(Config!$B$3="FR","Poids similitude gm","gm similarity weight") -> gm similarity weight | B28: 0.15 | D28: =IF(Config!$B$3="FR","gm modélisé au même courant Q17.","gm modeled at the same Q17 current.") -> gm modeled at the same Q17 current.
A29: =IF(Config!$B$3="FR","Poids similitude Crss","Crss similarity weight") -> Crss similarity weight | B29: 0.1 | D29: =IF(Config!$B$3="FR","Couplage drain-grille dynamique.","Dynamic drain-gate coupling.") -> Dynamic drain-gate coupling.
A30: =IF(Config!$B$3="FR","Poids similitude VGS","VGS similarity weight") -> VGS similarity weight | B30: 0.1 | D30: =IF(Config!$B$3="FR","Contribution de transfert, volontairement modérée.","Deliberately moderate transfer contribution.") -> Deliberately moderate transfer contribution.
A31: =IF(Config!$B$3="FR","Total poids paire","Total pair weight") -> Total pair weight | B31: =SUM(B25:B30) -> 1 | D31: =IF(Config!$B$3="FR","Doit être égal à 1,00.","Must equal 1.00.") -> Must equal 1.00.
A33: =IF(Config!$B$3="FR","PROFIL Ceff DU FOLLOWER","FOLLOWER Ceff PROFILE") -> FOLLOWER Ceff PROFILE
A34: =IF(Config!$B$3="FR","Poids état Av = 0,00","Av = 0.00 state weight") -> Av = 0.00 state weight | B34: 0.25 | D34: =IF(Config!$B$3="FR","Début de transition / source quasi immobile.","Start of transition / source nearly stationary.") -> Start of transition / source nearly stationary.
A35: =IF(Config!$B$3="FR","Poids état Av = 0,50","Av = 0.50 state weight") -> Av = 0.50 state weight | B35: 0.35 | D35: =IF(Config!$B$3="FR","État intermédiaire.","Intermediate state.") -> Intermediate state.
A36: =IF(Config!$B$3="FR","Poids état Av = 0,95","Av = 0.95 state weight") -> Av = 0.95 state weight | B36: 0.4 | D36: =IF(Config!$B$3="FR","Source follower actif ; Cgs largement bootstrapée.","Active source follower; Cgs largely bootstrapped.") -> Active source follower; Cgs largely bootstrapped.
A37: =IF(Config!$B$3="FR","Total poids états","Total state weights") -> Total state weights | B37: =SUM(B34:B36) -> 1 | D37: =IF(Config!$B$3="FR","Doit être égal à 1,00.","Must equal 1.00.") -> Must equal 1.00.
A39: =IF(Config!$B$3="FR","Av de référence pour R14/R15","Reference Av for R14/R15") -> Reference Av for R14/R15 | B39: 0.5 | D39: =IF(Config!$B$3="FR","Utilisé uniquement pour la légère compensation Rgate après sélection de la paire.","Used only for small Rgate compensation after pair selection.") -> Used only for small Rgate compensation after pair selection.
A41: =IF(Config!$B$3="FR","CLASSEMENT THÉORIQUE SIMPLIFIÉ","SIMPLIFIED THEORETICAL CLASSIFICATION") -> SIMPLIFIED THEORETICAL CLASSIFICATION
A42: =IF(Config!$B$3="FR","Ceff min classe A","Class A min Ceff") -> Class A min Ceff | B42: 0.82 | D42: =IF(Config!$B$3="FR","Similarité du profil Ceff N/P.","N/P Ceff profile similarity.") -> N/P Ceff profile similarity.
A43: =IF(Config!$B$3="FR","Équilibre Rgate min classe A","Class A min Rgate balance") -> Class A min Rgate balance | B43: 0.75 | D43: =IF(Config!$B$3="FR","MIN(R14,R15)/MAX(R14,R15), valeurs cibles E24.","MIN(R14,R15)/MAX(R14,R15), E24 target values.") -> MIN(R14,R15)/MAX(R14,R15), E24 target values.
A44: =IF(Config!$B$3="FR","Ceff min classe B","Class B min Ceff") -> Class B min Ceff | B44: 0.78
A45: =IF(Config!$B$3="FR","Équilibre Rgate min classe B","Class B min Rgate balance") -> Class B min Rgate balance | B45: 0.75
...

Sheet Selection
A1: =IF(Config!$B$3="FR","Q17-Mini — Sélection Q15/Q16 pour current-dumping & R14/R15 initiales","Q17-Mini — Q15/Q16 selection for current-dumping & initial R14/R15") -> Q17-Mini — Q15/Q16 selection for current-dumping & initial R14/R15
A2: =IF(Config!$B$3="FR","1.1b35 — Statut d’essai structuré → R14/R15 initiales → validation au scope.","1.1b35 — Structured test status → initial R14/R15 → oscilloscope validation.") -> 1.1b35 — Structured test status → initial R14/R15 → oscilloscope validation.
A3: =IF(Config!$B$3="FR","Paire sélectionnée","Selected pair") -> Selected pair | B3: (C16) IXTQ74N20P/FQA36P15 | D3: =IF(Config!$B$3="FR","Version","Version") -> Version | E3: =Config!$B$5 -> 1.1b35 | G3: =IF(Config!$B$3="FR","Langue","Language") -> Language | H3: =Config!$B$3 -> EN | I3: =IF(Config!$B$3="FR","Date","Date") -> Date | J3: =Config!$B$6 -> 08/10/2026 | M3: =IFERROR(MID(B3,FIND("(",B3)+1,FIND(")",B3)-FIND("(",B3)-1),"") -> C16
A4: =IF(Config!$B$3="FR","SYNTHÈSE DE LA PAIRE","PAIR SUMMARY") -> PAIR SUMMARY
A5: =IF(Config!$B$3="FR","Paramètre","Parameter") -> Parameter | B5: =IF(Config!$B$3="FR","Valeur","Value") -> Value | D5: MOSFET | E5: Ciss pF | F5: Crss pF | G5: Qgd nC | H5: gm mod. S | I5: VGS @3.125A | J5: =IF(Config!$B$3="FR","Aptitude","Suitability") -> Suitability
A6: Q15 (N) | B6: =IFERROR(VLOOKUP($M$3,Calculations!$A$5:$BM$22,2,FALSE),"") -> IXTQ74N20P | D6: Q15 | E6: =IFERROR(VLOOKUP($M$3,Calculations!$A$5:$BM$22,12,FALSE),"") -> 3300 | F6: =IFERROR(VLOOKUP($M$3,Calculations!$A$5:$BM$22,16,FALSE),"") -> 190 | G6: =IFERROR(VLOOKUP($M$3,Calculations!$A$5:$CC$22,69,FALSE),"") -> 52 | H6: =IFERROR(VLOOKUP($M$3,Calculations!$A$5:$CC$22,28,FALSE),"") -> 12.78724 | I6: =IFERROR(VLOOKUP($M$3,Calculations!$A$5:$CC$22,26,FALSE),"") -> 4.6 | J6: =IFERROR(VLOOKUP($M$3,Calculations!$A$5:$CC$22,58,FALSE),"") -> OK
A7: Q16 (P) | B7: =IFERROR(VLOOKUP($M$3,Calculations!$A$5:$BM$22,3,FALSE),"") -> FQA36P15 | D7: Q16 | E7: =IFERROR(VLOOKUP($M$3,Calculations!$A$5:$BM$22,13,FALSE),"") -> 2550 | F7: =IFERROR(VLOOKUP($M$3,Calculations!$A$5:$BM$22,17,FALSE),"") -> 110 | G7: =IFERROR(VLOOKUP($M$3,Calculations!$A$5:$CC$22,70,FALSE),"") -> 42 | H7: =IFERROR(VLOOKUP($M$3,Calculations!$A$5:$CC$22,29,FALSE),"") -> 8.125 | I7: =IFERROR(VLOOKUP($M$3,Calculations!$A$5:$CC$22,27,FALSE),"") -> 4.3 | J7: =IFERROR(VLOOKUP($M$3,Calculations!$A$5:$CC$22,59,FALSE),"") -> OK
A8: =IF(Config!$B$3="FR","R14 initiale (Ω)","Initial R14 (Ω)") -> Initial R14 (Ω) | B8: =IFERROR(VLOOKUP($M$3,Calculations!$A$5:$BM$22,54,FALSE),"") -> 100
A9: =IF(Config!$B$3="FR","R15 initiale (Ω)","Initial R15 (Ω)") -> Initial R15 (Ω) | B9: =IFERROR(VLOOKUP($M$3,Calculations!$A$5:$BM$22,55,FALSE),"") -> 130 | D9: =IF(Config!$B$3="FR","Plage théorique","Theoretical range") -> Theoretical range | E9: =IF(Config!$B$3="FR","R min E24","E24 min R") -> E24 min R | F9: =IF(Config!$B$3="FR","R max E24","E24 max R") -> E24 max R | G9: =IF(Config!$B$3="FR","Statut","Status") -> Status | I9: =IF(Config!$B$3="FR","Évaluation théorique","Theoretical assessment") -> Theoretical assessment | J9: =IF(Config!$B$3="FR","Valeur","Value") -> Value
A10: =IF(Config!$B$3="FR","Origine","Origin") -> Origin | B10: =IF(Config!$B$3="FR",IFERROR(VLOOKUP($M$3,Calculations!$A$5:$BM$22,56,FALSE),""),IF(IFERROR(VLOOKUP($M$3,Calculations!$A$5:$BM$22,56,FALSE),"")="CIBLE INITIALE","INITIAL TARGET",IF(IFERROR(VLOOKUP($M$3,Calculations!$A$5:$BM$22,56,FALSE),"")="CALCUL THÉORIQUE INITIAL","INITIAL THEORETICAL CALCULATION",IF(IFERROR(VLOOKUP($M$3,Calculations!$A$5:$BM$22,56,FALSE),"")="TEST Q17","Q17 TEST",IFERROR(VLOOKUP($M$3,Calculations!$A$5:$BM$22,56,FALSE),""))))) -> INITIAL TARGET | D10: R14 | E10: =IFERROR(VLOOKUP($M$3,Calculations!$A$5:$BM$22,36,FALSE),"") -> 10 | F10: =IFERROR(VLOOKUP($M$3,Calculations!$A$5:$BM$22,49,FALSE),"") -> 620 | G10: =IF(AND(B8>=E10,B8<=F10),"OK",IF(Config!$B$3="FR","À CONTRÔLER","CHECK")) -> OK | I10: =IF(Config!$B$3="FR","Classe","Class") -> Class | J10: =IF(Config!$B$3="FR",IFERROR(VLOOKUP($M$3,Calculations!$A$5:$CH$22,82,FALSE),""),IF(IFERROR(VLOOKUP($M$3,Calculations!$A$5:$CH$22,82,FALSE),"")="A – TRÈS BON CANDIDAT","A – VERY GOOD CANDIDATE",IF(IFERROR(VLOOKUP($M$3,Calculations!$A$5:$CH$22,82,FALSE),"")="B – BON CANDIDAT","B – GOOD CANDIDATE",IF(IFERROR(VLOOKUP($M$3,Calculations!$A$5:$CH$22,82,FALSE),"")="C – À ÉTUDIER","C – NEEDS REVIEW",IF(IFERROR(VLOOKUP($M$3,Calculations!$A$5:$CH$22,82,FALSE),"")="X – INADAPTÉ","X – UNSUITABLE",IFERROR(VLOOKUP($M$3,Calculations!$A$5:$CH$22,82,FALSE),"")))))) -> C – NEEDS REVIEW
A11: =IF(Config!$B$3="FR","Écart N/P","N/P mismatch") -> N/P mismatch | B11: =IFERROR(VLOOKUP($M$3,Calculations!$A$5:$BM$22,57,FALSE),"") -> 0.009253904 | D11: R15 | E11: =IFERROR(VLOOKUP($M$3,Calculations!$A$5:$BM$22,37,FALSE),"") -> 10 | F11: =IFERROR(VLOOKUP($M$3,Calculations!$A$5:$BM$22,50,FALSE),"") -> 910 | G11: =IF(AND(B9>=E11,B9<=F11),"OK",IF(Config!$B$3="FR","À CONTRÔLER","CHECK")) -> OK | I11: =IF(Config!$B$3="FR","Profil Ceff","Ceff profile") -> Ceff profile | J11: =IFERROR(VLOOKUP($M$3,Calculations!$A$5:$CH$22,61,FALSE),"") -> 0.72854023
A12: =IF(Config!$B$3="FR","Compatibilité Q17 théorique","Theoretical Q17 compatibility") -> Theoretical Q17 compatibility | B12: =IF(Config!$B$3="FR",IFERROR(VLOOKUP($M$3,Calculations!$A$5:$CH$22,82,FALSE),""),IF(IFERROR(VLOOKUP($M$3,Calculations!$A$5:$CH$22,82,FALSE),"")="A – TRÈS BON CANDIDAT","A – VERY GOOD CANDIDATE",IF(IFERROR(VLOOKUP($M$3,Calculations!$A$5:$CH$22,82,FALSE),"")="B – BON CANDIDAT","B – GOOD CANDIDATE",IF(IFERROR(VLOOKUP($M$3,Calculations!$A$5:$CH$22,82,FALSE),"")="C – À ÉTUDIER","C – NEEDS REVIEW",IF(IFERROR(VLOOKUP($M$3,Calculations!$A$5:$CH$22,82,FALSE),"")="X – INADAPTÉ","X – UNSUITABLE",IFERROR(VLOOKUP($M$3,Calculations!$A$5:$CH$22,82,FALSE),"")))))) -> C – NEEDS REVIEW | I12: =IF(Config!$B$3="FR","Équilibre Rgate","Rgate balance") -> Rgate balance | J12: =IFERROR(VLOOKUP($M$3,Calculations!$A$5:$CH$22,83,FALSE),"") -> 0.76923077
D13: =IF(Config!$B$3="FR","Nb alertes","Alert count") -> Alert count | E13: Qgd | F13: Qg | G13: gm | H13: Crss | I13: VGS | J13: =IF(Config!$B$3="FR","Alertes","Alerts") -> Alerts
D14: =IFERROR(VLOOKUP($M$3,Calculations!$A$5:$CH$22,84,FALSE),"") -> 0 | E14: =IFERROR(VLOOKUP($M$3,Calculations!$A$5:$CH$22,62,FALSE),"") -> 0.80769231 | F14: =IFERROR(VLOOKUP($M$3,Calculations!$A$5:$CH$22,63,FALSE),"") -> 0.75700935 | G14: =IFERROR(VLOOKUP($M$3,Calculations!$A$5:$CH$22,64,FALSE),"") -> 0.63539903 | H14: =IFERROR(VLOOKUP($M$3,Calculations!$A$5:$CH$22,65,FALSE),"") -> 0.57894737 | I14: =IFERROR(VLOOKUP($M$3,Calculations!$A$5:$CH$22,66,FALSE),"") -> 0.93478261 | J14: =IF(Config!$B$3="FR",IFERROR(VLOOKUP($M$3,Calculations!$A$5:$CH$22,85,FALSE),""),IF(IFERROR(VLOOKUP($M$3,Calculations!$A$5:$CH$22,85,FALSE),"")="Aucune","None",IFERROR(VLOOKUP($M$3,Calculations!$A$5:$CH$22,85,FALSE),""))) -> None
A15: =IF(Config!$B$3="FR","REGISTRE DE VALIDATION PHYSIQUE Q17","Q17 PHYSICAL VALIDATION LOG") -> Q17 PHYSICAL VALIDATION LOG
A16: =IF(Config!$B$3="FR","Paire","Pair") -> Pair | B16: Q15 | C16: Q16 | D16: =IF(Config!$B$3="FR","Statut essai Q17","Q17 test status") -> Q17 test status | E16: =IF(Config!$B$3="FR","R14 testée (Ω)","Tested R14 (Ω)") -> Tested R14 (Ω) | F16: =IF(Config!$B$3="FR","R15 testée (Ω)","Tested R15 (Ω)") -> Tested R15 (Ω) | G16: Notes essai FR | H16: Test notes EN | I16: =IF(Config!$B$3="FR","État validation","Validation state") -> Validation state
A17: S1 | B17: FQA46N15 | C17: FQA36P15 | D17: NON TESTÉ / NOT TESTED | G17: Configuration historique / défaut. | H17: Historical / default configuration. | I17: =IF(D17="TESTÉ – À ÉVALUER / TESTED – TO REVIEW",IF(Config!$B$3="FR","À ÉVALUER","TO REVIEW"),IF(D17="VALIDÉ / VALIDATED",IF(AND(E17>0,F17>0),IF(Config!$B$3="FR","COMPLÈTE","COMPLETE"),IF(Config!$B$3="FR","INCOMPLÈTE","INCOMPLETE")),IF(D17="REJETÉ / REJECTED",IF(Config!$B$3="FR","REJETÉ","REJECTED"),"—"))) -> — | M17: (S1) FQA46N15/FQA36P15
A18: S3 | B18: IXTQ36N30P | C18: FQA36P15 | D18: VALIDÉ / VALIDATED | E18: 47 | F18: 47 | G18: Test effectué sur PCB 3.0.4. | H18: Test performed on PCB 3.0.4. | I18: =IF(D18="TESTÉ – À ÉVALUER / TESTED – TO REVIEW",IF(Config!$B$3="FR","À ÉVALUER","TO REVIEW"),IF(D18="VALIDÉ / VALIDATED",IF(AND(E18>0,F18>0),IF(Config!$B$3="FR","COMPLÈTE","COMPLETE"),IF(Config!$B$3="FR","INCOMPLÈTE","INCOMPLETE")),IF(D18="REJETÉ / REJECTED",IF(Config!$B$3="FR","REJETÉ","REJECTED"),"—"))) -> COMPLETE | M18: (S3) IXTQ36N30P/FQA36P15
A19: S4 | B19: IXTQ36N30P | C19: IXTQ36P15P | D19: NON TESTÉ / NOT TESTED | G19: Combinaison à valider sur Q17. | H19: Combination to validate on Q17. | I19: =IF(D19="TESTÉ – À ÉVALUER / TESTED – TO REVIEW",IF(Config!$B$3="FR","À ÉVALUER","TO REVIEW"),IF(D19="VALIDÉ / VALIDATED",IF(AND(E19>0,F19>0),IF(Config!$B$3="FR","COMPLÈTE","COMPLETE"),IF(Config!$B$3="FR","INCOMPLÈTE","INCOMPLETE")),IF(D19="REJETÉ / REJECTED",IF(Config!$B$3="FR","REJETÉ","REJECTED"),"—"))) -> — | M19: (S4) IXTQ36N30P/IXTQ36P15P
A20: S5 | B20: FQA46N15 | C20: IXTQ36P15P | D20: TESTÉ – À ÉVALUER / TESTED – TO REVIEW | G20: Combinaison à valider sur Q17. | H20: Combination to validate on Q17. | I20: =IF(D20="TESTÉ – À ÉVALUER / TESTED – TO REVIEW",IF(Config!$B$3="FR","À ÉVALUER","TO REVIEW"),IF(D20="VALIDÉ / VALIDATED",IF(AND(E20>0,F20>0),IF(Config!$B$3="FR","COMPLÈTE","COMPLETE"),IF(Config!$B$3="FR","INCOMPLÈTE","INCOMPLETE")),IF(D20="REJETÉ / REJECTED",IF(Config!$B$3="FR","REJETÉ","REJECTED"),"—"))) -> TO REVIEW | M20: (S5) FQA46N15/IXTQ36P15P
A21: C1 | B21: IXTQ50N20P | C21: IXTQ36P15P | D21: TESTÉ – À ÉVALUER / TESTED – TO REVIEW | G21: Combinaison à valider sur Q17. | H21: Combination to validate on Q17. | I21: =IF(D21="TESTÉ – À ÉVALUER / TESTED – TO REVIEW",IF(Config!$B$3="FR","À ÉVALUER","TO REVIEW"),IF(D21="VALIDÉ / VALIDATED",IF(AND(E21>0,F21>0),IF(Config!$B$3="FR","COMPLÈTE","COMPLETE"),IF(Config!$B$3="FR","INCOMPLÈTE","INCOMPLETE")),IF(D21="REJETÉ / REJECTED",IF(Config!$B$3="FR","REJETÉ","REJECTED"),"—"))) -> TO REVIEW | M21: (C1) IXTQ50N20P/IXTQ36P15P
A22: C3 | B22: IXTQ50N20P | C22: FQA36P15 | D22: TESTÉ – À ÉVALUER / TESTED – TO REVIEW | G22: Combinaison à valider sur Q17. | H22: Combination to validate on Q17. | I22: =IF(D22="TESTÉ – À ÉVALUER / TESTED – TO REVIEW",IF(Config!$B$3="FR","À ÉVALUER","TO REVIEW"),IF(D22="VALIDÉ / VALIDATED",IF(AND(E22>0,F22>0),IF(Config!$B$3="FR","COMPLÈTE","COMPLETE"),IF(Config!$B$3="FR","INCOMPLÈTE","INCOMPLETE")),IF(D22="REJETÉ / REJECTED",IF(Config!$B$3="FR","REJETÉ","REJECTED"),"—"))) -> TO REVIEW | M22: (C3) IXTQ50N20P/FQA36P15
A23: C5 | B23: FQA46N15 | C23: IXTQ26P20P | D23: NON TESTÉ / NOT TESTED | G23: Combinaison à valider sur Q17. | H23: Combination to validate on Q17. | I23: =IF(D23="TESTÉ – À ÉVALUER / TESTED – TO REVIEW",IF(Config!$B$3="FR","À ÉVALUER","TO REVIEW"),IF(D23="VALIDÉ / VALIDATED",IF(AND(E23>0,F23>0),IF(Config!$B$3="FR","COMPLÈTE","COMPLETE"),IF(Config!$B$3="FR","INCOMPLÈTE","INCOMPLETE")),IF(D23="REJETÉ / REJECTED",IF(Config!$B$3="FR","REJETÉ","REJECTED"),"—"))) -> — | M23: (C5) FQA46N15/IXTQ26P20P
A24: C6 | B24: IXTQ36N30P | C24: IXTQ26P20P | D24: NON TESTÉ / NOT TESTED | G24: Combinaison à valider sur Q17. | H24: Combination to validate on Q17. | I24: =IF(D24="TESTÉ – À ÉVALUER / TESTED – TO REVIEW",IF(Config!$B$3="FR","À ÉVALUER","TO REVIEW"),IF(D24="VALIDÉ / VALIDATED",IF(AND(E24>0,F24>0),IF(Config!$B$3="FR","COMPLÈTE","COMPLETE"),IF(Config!$B$3="FR","INCOMPLÈTE","INCOMPLETE")),IF(D24="REJETÉ / REJECTED",IF(Config!$B$3="FR","REJETÉ","REJECTED"),"—"))) -> — | M24: (C6) IXTQ36N30P/IXTQ26P20P
A25: C7 | B25: IXTQ50N20P | C25: IXTQ26P20P | D25: VALIDÉ / VALIDATED | G25: Combinaison à valider sur Q17. | H25: Combination to validate on Q17. | I25: =IF(D25="TESTÉ – À ÉVALUER / TESTED – TO REVIEW",IF(Config!$B$3="FR","À ÉVALUER","TO REVIEW"),IF(D25="VALIDÉ / VALIDATED",IF(AND(E25>0,F25>0),IF(Config!$B$3="FR","COMPLÈTE","COMPLETE"),IF(Config!$B$3="FR","INCOMPLÈTE","INCOMPLETE")),IF(D25="REJETÉ / REJECTED",IF(Config!$B$3="FR","REJETÉ","REJECTED"),"—"))) -> INCOMPLETE | M25: (C7) IXTQ50N20P/IXTQ26P20P
A26: C16 | B26: IXTQ74N20P | C26: FQA36P15 | D26: NON TESTÉ / NOT TESTED | G26: Combinaison à valider sur Q17. | H26: Combination to validate on Q17. | I26: =IF(D26="TESTÉ – À ÉVALUER / TESTED – TO REVIEW",IF(Config!$B$3="FR","À ÉVALUER","TO REVIEW"),IF(D26="VALIDÉ / VALIDATED",IF(AND(E26>0,F26>0),IF(Config!$B$3="FR","COMPLÈTE","COMPLETE"),IF(Config!$B$3="FR","INCOMPLÈTE","INCOMPLETE")),IF(D26="REJETÉ / REJECTED",IF(Config!$B$3="FR","REJETÉ","REJECTED"),"—"))) -> — | M26: (C16) IXTQ74N20P/FQA36P15
A27: C17 | B27: IXTQ74N20P | C27: IXTQ36P15P | D27: NON TESTÉ / NOT TESTED | G27: Combinaison à valider sur Q17. | H27: Combination to validate on Q17. | I27: =IF(D27="TESTÉ – À ÉVALUER / TESTED – TO REVIEW",IF(Config!$B$3="FR","À ÉVALUER","TO REVIEW"),IF(D27="VALIDÉ / VALIDATED",IF(AND(E27>0,F27>0),IF(Config!$B$3="FR","COMPLÈTE","COMPLETE"),IF(Config!$B$3="FR","INCOMPLÈTE","INCOMPLETE")),IF(D27="REJETÉ / REJECTED",IF(Config!$B$3="FR","REJETÉ","REJECTED"),"—"))) -> — | M27: (C17) IXTQ74N20P/IXTQ36P15P
A28: C19 | B28: IXTQ74N20P | C28: IXTQ26P20P | D28: REJETÉ / REJECTED | G28: Combinaison à valider sur Q17. | H28: Combination to validate on Q17. | I28: =IF(D28="TESTÉ – À ÉVALUER / TESTED – TO REVIEW",IF(Config!$B$3="FR","À ÉVALUER","TO REVIEW"),IF(D28="VALIDÉ / VALIDATED",IF(AND(E28>0,F28>0),IF(Config!$B$3="FR","COMPLÈTE","COMPLETE"),IF(Config!$B$3="FR","INCOMPLÈTE","INCOMPLETE")),IF(D28="REJETÉ / REJECTED",IF(Config!$B$3="FR","REJETÉ","REJECTED"),"—"))) -> REJECTED | M28: (C19) IXTQ74N20P/IXTQ26P20P
A29: C20 | B29: FDA38N30 | C29: FQA36P15 | D29: NON TESTÉ / NOT TESTED | G29: Combinaison à valider sur Q17. | H29: Combination to validate on Q17. | I29: =IF(D29="TESTÉ – À ÉVALUER / TESTED – TO REVIEW",IF(Config!$B$3="FR","À ÉVALUER","TO REVIEW"),IF(D29="VALIDÉ / VALIDATED",IF(AND(E29>0,F29>0),IF(Config!$B$3="FR","COMPLÈTE","COMPLETE"),IF(Config!$B$3="FR","INCOMPLÈTE","INCOMPLETE")),IF(D29="REJETÉ / REJECTED",IF(Config!$B$3="FR","REJETÉ","REJECTED"),"—"))) -> — | M29: (C20) FDA38N30/FQA36P15
A30: C21 | B30: FDA38N30 | C30: IXTQ36P15P | D30: NON TESTÉ / NOT TESTED | G30: Combinaison à valider sur Q17. | H30: Combination to validate on Q17. | I30: =IF(D30="TESTÉ – À ÉVALUER / TESTED – TO REVIEW",IF(Config!$B$3="FR","À ÉVALUER","TO REVIEW"),IF(D30="VALIDÉ / VALIDATED",IF(AND(E30>0,F30>0),IF(Config!$B$3="FR","COMPLÈTE","COMPLETE"),IF(Config!$B$3="FR","INCOMPLÈTE","INCOMPLETE")),IF(D30="REJETÉ / REJECTED",IF(Config!$B$3="FR","REJETÉ","REJECTED"),"—"))) -> — | M30: (C21) FDA38N30/IXTQ36P15P
... A34: C25 | B34: STW46NF30 | C34: IXTQ26P20P | D34: NON TESTÉ / NOT TESTED | G34: Combinaison à valider sur Q17. | H34: Combination to validate on Q17. | I34: =IF(D34="TESTÉ – À ÉVALUER / TESTED – TO REVIEW",IF(Config!$B$3="FR","À ÉVALUER","TO REVIEW"),IF(D34="VALIDÉ / VALIDATED",IF(AND(E34>0,F34>0),IF(Config!$B$3="FR","COMPLÈTE","COMPLETE"),IF(Config!$B$3="FR","INCOMPLÈTE","INCOMPLETE")),IF(D34="REJETÉ / REJECTED",IF(Config!$B$3="FR","REJETÉ","REJECTED"),"—"))) -> — | M34: (C25) STW46NF30/IXTQ26P20P
A36: =IF(Config!$B$3="FR","Le statut essai Q17 pilote le moteur. Les notes FR/EN sont uniquement descriptives. Seul VALIDÉ / VALIDATED avec R14 et R15 testées renseignées remplace les valeurs théoriques.","Q17 test status drives the engine. FR/EN notes are descriptive only. Only VALIDÉ / VALIDATED with both tested R14 and R15 filled in overrides the theoretical values.") -> Q17 test status drives the engine. FR/EN notes are descriptive only. Only VALIDÉ / VALIDATED with both tested R14 and R15 filled in overrides the theoretical values.

Sheet Calculations
A1: Q17-Mini — Aptitude MOSFET → Compatibilité Q15/Q16 → R14/R15 initiales
A2: 1.1b2 : le classement principal recherche d’abord une paire intrinsèquement adaptée au current-dumping. R14/R15 n’interviennent qu’ensuite comme réglage secondaire et restent à valider à l’oscilloscope.
A4: Paire | B4: Q15 (N) | C4: Q16 (P) | D4: Statut essai Q17 | E4: R14 testée | F4: R15 testée | G4: Note essai affichée | H4: Vdss N | I4: Vdss P | J4: Idmax N | K4: Idmax P | L4: Ciss N | M4: Ciss P | N4: Coss N | O4: Coss P | P4: Crss N | Q4: Crss P | R4: gfs N | S4: gfs P | T4: Id@gfs N | U4: Id@gfs P | V4: Rg int N | W4: Rg int P | X4: Qg N | Y4: Qg P | Z4: VGS N | AA4: VGS P | AB4: gm N | AC4: gm P | AD4: f0 N MHz | AE4: f0 P MHz | AF4: Rneg N | AG4: Rneg P | AH4: Rmin N | AI4: Rmin P | AJ4: E24 min N | AK4: E24 min P | AL4: fGate max N MHz | AM4: fGate max P MHz | AN4: f cible paire MHz | AO4: R14 idéale | AP4: R15 idéale | AQ4: R14 théorique E24 | AR4: R15 théorique E24 | AS4: Ceff N pF | AT4: Ceff P pF | AU4: Rmax N | AV4: Rmax P | AW4: E24 max N | AX4: E24 max P | AY4: R14 cible E24 | AZ4: R15 cible E24 | BA4: Cible valide | BB4: R14 initiale | BC4: R15 initiale | BD4: Origine | BE4: Écart N/P Rgate (Ceff ref) | BF4: Aptitude Q15 | BG4: Aptitude Q16 | BH4: Compatibilité Q17 | BI4: Score profil Ceff | BJ4: Sim. Qgd | BK4: Sim. Qg | BL4: Sim. gm | BM4: Sim. Crss | BN4: Sim. VGS | BO4: Indice compatibilité paire | BP4: Note paire | BQ4: Qgd N | BR4: Qgd P | BS4: Ceff N Av0 | BT4: Ceff P Av0 | BU4: Ceff N Av0.5 | BV4: Ceff P Av0.5 | BW4: Ceff N Av0.95 | BX4: Ceff P Av0.95 | BY4: Sim. Ceff Av0 | BZ4: Sim. Ceff Av0.5 | CA4: Sim. Ceff Av0.95 | CB4: Ceff N Av ref | CC4: Ceff P Av ref | CD4: Classe théorique | CE4: Équilibre Rgate | CF4: Nb alertes | CG4: Alertes | CH4: Retour essai Q17
A5: S1 | B5: FQA46N15 | C5: FQA36P15 | D5: =IFERROR(VLOOKUP(A5,Selection!$A$17:$I$28,4,FALSE),"NON TESTÉ / NOT TESTED") -> NON TESTÉ / NOT TESTED | E5: =IFERROR(VLOOKUP(A5,Selection!$A$17:$I$28,5,FALSE),"") -> 0 | F5: =IFERROR(VLOOKUP(A5,Selection!$A$17:$I$28,6,FALSE),"") -> 0 | G5: =IF(Config!$B$3="FR",IFERROR(T(VLOOKUP(A5,Selection!$A$17:$I$28,7,FALSE)),""),IF(IFERROR(T(VLOOKUP(A5,Selection!$A$17:$I$28,8,FALSE)),"")<>"",IFERROR(T(VLOOKUP(A5,Selection!$A$17:$I$28,8,FALSE)),""),IFERROR(T(VLOOKUP(A5,Selection!$A$17:$I$28,7,FALSE)),""))) -> Historical / default configuration. | H5: =IFERROR(VLOOKUP($B5,MOSFET!$A$2:$Q$11,5,FALSE),"") -> 150 | I5: =IFERROR(VLOOKUP($C5,MOSFET!$A$2:$Q$11,5,FALSE),"") -> 150 | J5: =IFERROR(VLOOKUP($B5,MOSFET!$A$2:$Q$11,6,FALSE),"") -> 50 | K5: =IFERROR(VLOOKUP($C5,MOSFET!$A$2:$Q$11,6,FALSE),"") -> 36 | L5: =IFERROR(VLOOKUP($B5,MOSFET!$A$2:$Q$11,7,FALSE),"") -> 2500 | M5: =IFERROR(VLOOKUP($C5,MOSFET!$A$2:$Q$11,7,FALSE),"") -> 2550 | N5: =IFERROR(VLOOKUP($B5,MOSFET!$A$2:$Q$11,8,FALSE),"") -> 520 | O5: =IFERROR(VLOOKUP($C5,MOSFET!$A$2:$Q$11,8,FALSE),"") -> 710 | P5: =IFERROR(VLOOKUP($B5,MOSFET!$A$2:$Q$11,9,FALSE),"") -> 100 | Q5: =IFERROR(VLOOKUP($C5,MOSFET!$A$2:$Q$11,9,FALSE),"") -> 110 | R5: =IFERROR(VLOOKUP($B5,MOSFET!$A$2:$Q$11,10,FALSE),"") -> 36 | S5: =IFERROR(VLOOKUP($C5,MOSFET!$A$2:$Q$11,10,FALSE),"") -> 19.5 | T5: =IFERROR(VLOOKUP($B5,MOSFET!$A$2:$Q$11,11,FALSE),"") -> 25 | U5: =IFERROR(VLOOKUP($C5,MOSFET!$A$2:$Q$11,11,FALSE),"") -> 18 | V5: =IFERROR(VLOOKUP($B5,MOSFET!$A$2:$Q$11,12,FALSE),0) -> 0 | W5: =IFERROR(VLOOKUP($C5,MOSFET!$A$2:$Q$11,12,FALSE),0) -> 0 | X5: =IFERROR(VLOOKUP($B5,MOSFET!$A$2:$Q$11,13,FALSE),"") -> 85 | Y5: =IFERROR(VLOOKUP($C5,MOSFET!$A$2:$Q$11,13,FALSE),"") -> 81 | Z5: =IFERROR(VLOOKUP($B5,MOSFET!$A$2:$Q$11,16,FALSE),"") -> 4.2 | AA5: =IFERROR(VLOOKUP($C5,MOSFET!$A$2:$Q$11,16,FALSE),"") -> 4.3 | AB5: =IFERROR(R5*SQRT(Config!$B$13/T5),"") -> 12.727922 | AC5: =IFERROR(S5*SQRT(Config!$B$13/U5),"") -> 8.125 | AD5: =IFERROR((1/(2*PI()))*SQRT((1+AB5*Config!$B$12)/(Config!$B$14*0.000000001*L5*0.000000000001))/1000000,"") -> 186.35259 | AE5: =IFERROR((1/(2*PI()))*SQRT((1+AC5*Config!$B$12)/(Config!$B$14*0.000000001*M5*0.000000000001))/1000000,"") -> 147.82959 | AF5: =IFERROR((AB5*N5*Config!$B$12^2/L5)/(1+(2*PI()*AD5*1000000*N5*0.000000000001*Config!$B$12)^2),"") -> 6.852577 | AG5: =IFERROR((AC5*O5*Config!$B$12^2/M5)/(1+(2*PI()*AE5*1000000*O5*0.000000000001*Config!$B$12)^2),"") -> 5.0212656 | AH5: =IF(AF5="","",MAX(0,Config!$B$16*AF5-V5-Config!$B$15)) -> 9.5936078 | AI5: =IF(AG5="","",MAX(0,Config!$B$16*AG5-W5-Config!$B$15)) -> 7.0297718 | AJ5: =IF(AH5="","",IF(AH5<=10,10,IF(AH5>=10000,10000,IF(VLOOKUP(AH5,Notes!$F$2:$G$74,1,TRUE)=AH5,AH5,VLOOKUP(AH5,Notes!$F$2:$G$74,2,TRUE))))) -> 10 | AK5: =IF(AI5="","",IF(AI5<=10,10,IF(AI5>=10000,10000,IF(VLOOKUP(AI5,Notes!$F$2:$G$74,1,TRUE)=AI5,AI5,VLOOKUP(AI5,Notes!$F$2:$G$74,2,TRUE))))) -> 10 | AL5: =IFERROR(1/(2*PI()*AJ5*L5*0.000000000001)/1000000,"") -> 6.3661977 | AM5: =IFERROR(1/(2*PI()*AK5*M5*0.000000000001)/1000000,"") -> 6.2413703 | AN5: =IF(OR(AL5="",AM5=""),"",MIN(AL5,AM5)) -> 6.2413703 | AO5: =IFERROR(1/(2*PI()*AN5*1000000*L5*0.000000000001),"") -> 10.2 | AP5: =IFERROR(1/(2*PI()*AN5*1000000*M5*0.000000000001),"") -> 10 | AQ5: =IF(AO5="","",IF(MAX(AH5,AO5)<=10,10,IF(MAX(AH5,AO5)>=10000,10000,IF(VLOOKUP(MAX(AH5,AO5),Notes!$F$2:$G$74,1,TRUE)=MAX(AH5,AO5),MAX(AH5,AO5),VLOOKUP(MAX(AH5,AO5),Notes!$F$2:$G$74,2,TRUE))))) -> 11 | AR5: =IF(AP5="","",IF(MAX(AI5,AP5)<=10,10,IF(MAX(AI5,AP5)>=10000,10000,IF(VLOOKUP(MAX(AI5,AP5),Notes!$F$2:$G$74,1,TRUE)=MAX(AI5,AP5),MAX(AI5,AP5),VLOOKUP(MAX(AI5,AP5),Notes!$F$2:$G$74,2,TRUE))))) -> 10 | AS5: =IFERROR(P5+(L5-P5)/(1+AB5*Config!$B$12),"") -> 123.341 | AT5: =IFERROR(Q5+(M5-Q5)/(1+AC5*Config!$B$12),"") -> 146.9697 | AU5: =IFERROR(MAX(0,MIN(TAN(RADIANS(Config!$B$21))/(2*PI()*Config!$B$20*1000*AS5*0.000000000001)-V5-Config!$B$15,SQRT(10^(Config!$B$22/10)-1)/(2*PI()*Config!$B$20*1000*AS5*0.000000000001)-V5-Config!$B$15)),"") -> 1128.9234 | AV5: =IFERROR(MAX(0,MIN(TAN(RADIANS(Config!$B$21))/(2*PI()*Config!$B$20*1000*AT5*0.000000000001)-W5-Config!$B$15,SQRT(10^(Config!$B$22/10)-1)/(2*PI()*Config!$B$20*1000*AT5*0.000000000001)-W5-Config!$B$15)),"") -> 947.42342 | AW5: =IF(AU5="","",IF(AU5<10,"<10",IF(AU5>=10000,10000,VLOOKUP(AU5,Notes!$F$2:$G$74,1,TRUE)))) -> 1100 | AX5: =IF(AV5="","",IF(AV5<10,"<10",IF(AV5>=10000,10000,VLOOKUP(AV5,Notes!$F$2:$G$74,1,TRUE)))) -> 910 | AY5: =IFERROR(IF((IF(Config!$B$8="R14",Config!$B$9,Config!$B$9*CC5/CB5))<=10,10,IF((IF(Config!$B$8="R14",Config!$B$9,Config!$B$9*CC5/CB5))>=10000,10000,IF(ABS((IF(Config!$B$8="R14",Config!$B$9,Config!$B$9*CC5/CB5))-VLOOKUP((IF(Config!$B$8="R14",Config!$B$9,Config!$B$9*CC5/CB5)),Notes!$F$2:$G$74,1,TRUE))<=ABS(VLOOKUP((IF(Config!$B$8="R14",Config!$B$9,Config!$B$9*CC5/CB5)),Notes!$F$2:$G$74,2,TRUE)-(IF(Config!$B$8="R14",Config!$B$9,Config!$B$9*CC5/CB5))),VLOOKUP((IF(Config!$B$8="R14",Config!$B$9,Config!$B$9*CC5/CB5)),Notes!$F$2:$G$74,1,TRUE),VLOOKUP((IF(Config!$B$8="R14",Config!$B$9,Config!$B$9*CC5/CB5)),Notes!$F$2:$G$74,2,TRUE)))),"") -> 100 | AZ5: =IFERROR(IF((IF(Config!$B$8="R15",Config!$B$9,Config!$B$9*CB5/CC5))<=10,10,IF((IF(Config!$B$8="R15",Config!$B$9,Config!$B$9*CB5/CC5))>=10000,10000,IF(ABS((IF(Config!$B$8="R15",Config!$B$9,Config!$B$9*CB5/CC5))-VLOOKUP((IF(Config!$B$8="R15",Config!$B$9,Config!$B$9*CB5/CC5)),Notes!$F$2:$G$74,1,TRUE))<=ABS(VLOOKUP((IF(Config!$B$8="R15",Config!$B$9,Config!$B$9*CB5/CC5)),Notes!$F$2:$G$74,2,TRUE)-(IF(Config!$B$8="R15",Config!$B$9,Config!$B$9*CB5/CC5))),VLOOKUP((IF(Config!$B$8="R15",Config!$B$9,Config!$B$9*CB5/CC5)),Notes!$F$2:$G$74,1,TRUE),VLOOKUP((IF(Config!$B$8="R15",Config!$B$9,Config!$B$9*CB5/CC5)),Notes!$F$2:$G$74,2,TRUE)))),"") -> 100 | BA5: =IF(OR(AW5="<10",AX5="<10"),"NO",IF(AND(AY5>=AJ5,AY5<=AW5,AZ5>=AK5,AZ5<=AX5,ABS(1/(AY5*L5)-1/(AZ5*M5))/MIN(1/(AY5*L5),1/(AZ5*M5))<=Config!$B$19),"YES","NO")) -> YES | BB5: =IF(AND(D5="VALIDÉ / VALIDATED",E5>0,F5>0),E5,IF(BA5="YES",AY5,AQ5)) -> 100 | BC5: =IF(AND(D5="VALIDÉ / VALIDATED",E5>0,F5>0),F5,IF(BA5="YES",AZ5,AR5)) -> 100 | BD5: =IF(AND(D5="VALIDÉ / VALIDATED",E5>0,F5>0),_xlfn.CONCAT("TEST Q",17),IF(BA5="YES","CIBLE INITIALE","CALCUL THÉORIQUE INITIAL")) -> CIBLE INITIALE | BE5: =IFERROR(ABS(BB5*CB5-BC5*CC5)/MIN(BB5*CB5,BC5*CC5),"") -> 0.023076923 | BF5: =IF(B5="","",IF(VLOOKUP(B5,MOSFET!$A$2:$Q$11,2,FALSE)<>"N","NON – canal",IF(H5<2*Config!$B$11*Config!$B$17,"NON – Vdss",IF(J5<Config!$B$13*Config!$B$18,"NON – Id",IF(L5>Config!$B$23,"NON – Ciss",IF(OR(L5="",P5="",X5="",BQ5="",R5="",T5="",Z5=""),"DONNÉES À COMPLÉTER","OK")))))) -> OK | BG5: =IF(C5="","",IF(VLOOKUP(C5,MOSFET!$A$2:$Q$11,2,FALSE)<>"P","NON – canal",IF(I5<2*Config!$B$11*Config!$B$17,"NON – Vdss",IF(K5<Config!$B$13*Config!$B$18,"NON – Id",IF(M5>Config!$B$23,"NON – Ciss",IF(OR(M5="",Q5="",Y5="",BR5="",S5="",U5="",AA5=""),"DONNÉES À COMPLÉTER","OK")))))) -> OK | BH5: =IF(OR(BF5<>"OK",BG5<>"OK"),"NON – aptitude MOSFET",IF(AND(D5="VALIDÉ / VALIDATED",E5>0,F5>0),_xlfn.CONCAT("OUI – Q",17," confirmé"),IF(BO5>=0.82,"OUI – paire prioritaire / test scope requis",IF(BO5>=0.74,"OUI – paire acceptable / test scope requis","À ÉVALUER – compatibilité faible")))) -> OUI – paire prioritaire / test scope requis | BI5: =IFERROR((Config!$B$34*BY5+Config!$B$35*BZ5+Config!$B$36*CA5)/Config!$B$37,"") -> 0.96651365 | BJ5: =IFERROR(MIN(BQ5,BR5)/MAX(BQ5,BR5),"") -> 0.97619048 | BK5: =IFERROR(MIN(X5,Y5)/MAX(X5,Y5),"") -> 0.95294118 | BL5: =IFERROR(MIN(AB5,AC5)/MAX(AB5,AC5),"") -> 0.63836029 | BM5: =IFERROR(MIN(P5,Q5)/MAX(P5,Q5),"") -> 0.90909091 | BN5: =IFERROR(MIN(Z5,AA5)/MAX(Z5,AA5),"") -> 0.97674419 | BO5: =IFERROR((Config!$B$25*BI5+Config!$B$26*BJ5+Config!$B$27*BK5+Config!$B$28*BL5+Config!$B$29*BM5+Config!$B$30*BN5)/Config!$B$31,"") -> 0.91247092 | BP5: =IF(OR(BF5<>"OK",BG5<>"OK"),1,IF(BO5>=0.9,5,IF(BO5>=0.82,4,IF(BO5>=0.74,3,IF(BO5>=0.66,2,1))))) -> 5 | BQ5: =IFERROR(VLOOKUP($B5,MOSFET!$A$2:$Q$11,14,FALSE),"") -> 41 | BR5: =IFERROR(VLOOKUP($C5,MOSFET!$A$2:$Q$11,14,FALSE),"") -> 42 | BS5: =IFERROR(P5+(L5-P5)*(1-0),"") -> 2500 | BT5: =IFERROR(Q5+(M5-Q5)*(1-0),"") -> 2550 | BU5: =IFERROR(P5+(L5-P5)*(1-0.5),"") -> 1300 | BV5: =IFERROR(Q5+(M5-Q5)*(1-0.5),"") -> 1330 | BW5: =IFERROR(P5+(L5-P5)*(1-0.95),"") -> 220 | BX5: =IFERROR(Q5+(M5-Q5)*(1-0.95),"") -> 232 | BY5: =IFERROR(MIN(BS5,BT5)/MAX(BS5,BT5),"") -> 0.98039216 | BZ5: =IFERROR(MIN(BU5,BV5)/MAX(BU5,BV5),"") -> 0.97744361 | CA5: =IFERROR(MIN(BW5,BX5)/MAX(BW5,BX5),"") -> 0.94827586 | CB5: =IFERROR(P5+(L5-P5)*(1-Config!$B$39),"") -> 1300 | CC5: =IFERROR(Q5+(M5-Q5)*(1-Config!$B$39),"") -> 1330 | CD5: =IF(OR(BF5<>"OK",BG5<>"OK"),"X – INADAPTÉ",IF(AND(BI5>=Config!$B$42,CE5>=Config!$B$43,CF5=0),"A – TRÈS BON CANDIDAT",IF(AND(BI5>=Config!$B$44,CE5>=Config!$B$45,CF5=0),"B – BON CANDIDAT","C – À ÉTUDIER"))) -> A – TRÈS BON CANDIDAT | CE5: =IFERROR(MIN(AY5,AZ5)/MAX(AY5,AZ5),"") -> 1 | CF5: =--(BJ5<Config!$B$46)+--(BK5<Config!$B$47)+--(BL5<Config!$B$47)+--(BM5<Config!$B$47)+--(BN5<Config!$B$48) -> 0 | CG5: =IF(CF5=0,"Aucune",IF(BJ5<Config!$B$46,"Qgd; ","")&IF(BK5<Config!$B$47,"Qg; ","")&IF(BL5<Config!$B$47,"gm; ","")&IF(BM5<Config!$B$47,"Crss; ","")&IF(BN5<Config!$B$48,"VGS; ","")) -> Aucune | CH5: =IF(D5="VALIDÉ / VALIDATED",IF(AND(E5>0,F5>0),"VALIDÉ R14/R15","VALIDATION INCOMPLÈTE"),IF(D5="TESTÉ – À ÉVALUER / TESTED – TO REVIEW","TESTÉ – À ÉVALUER",IF(D5="REJETÉ / REJECTED","REJETÉ","NON TESTÉ"))) -> NON TESTÉ
A6: S3 | B6: IXTQ36N30P | C6: FQA36P15 | D6: =IFERROR(VLOOKUP(A6,Selection!$A$17:$I$28,4,FALSE),"NON TESTÉ / NOT TESTED") -> VALIDÉ / VALIDATED | E6: =IFERROR(VLOOKUP(A6,Selection!$A$17:$I$28,5,FALSE),"") -> 47 | F6: =IFERROR(VLOOKUP(A6,Selection!$A$17:$I$28,6,FALSE),"") -> 47 | G6: =IF(Config!$B$3="FR",IFERROR(T(VLOOKUP(A6,Selection!$A$17:$I$28,7,FALSE)),""),IF(IFERROR(T(VLOOKUP(A6,Selection!$A$17:$I$28,8,FALSE)),"")<>"",IFERROR(T(VLOOKUP(A6,Selection!$A$17:$I$28,8,FALSE)),""),IFERROR(T(VLOOKUP(A6,Selection!$A$17:$I$28,7,FALSE)),""))) -> Test performed on PCB 3.0.4. | H6: =IFERROR(VLOOKUP($B6,MOSFET!$A$2:$Q$11,5,FALSE),"") -> 300 | I6: =IFERROR(VLOOKUP($C6,MOSFET!$A$2:$Q$11,5,FALSE),"") -> 150 | J6: =IFERROR(VLOOKUP($B6,MOSFET!$A$2:$Q$11,6,FALSE),"") -> 36 | K6: =IFERROR(VLOOKUP($C6,MOSFET!$A$2:$Q$11,6,FALSE),"") -> 36 | L6: =IFERROR(VLOOKUP($B6,MOSFET!$A$2:$Q$11,7,FALSE),"") -> 2250 | M6: =IFERROR(VLOOKUP($C6,MOSFET!$A$2:$Q$11,7,FALSE),"") -> 2550 | N6: =IFERROR(VLOOKUP($B6,MOSFET!$A$2:$Q$11,8,FALSE),"") -> 370 | O6: =IFERROR(VLOOKUP($C6,MOSFET!$A$2:$Q$11,8,FALSE),"") -> 710 | P6: =IFERROR(VLOOKUP($B6,MOSFET!$A$2:$Q$11,9,FALSE),"") -> 90 | Q6: =IFERROR(VLOOKUP($C6,MOSFET!$A$2:$Q$11,9,FALSE),"") -> 110 | R6: =IFERROR(VLOOKUP($B6,MOSFET!$A$2:$Q$11,10,FALSE),"") -> 22 | S6: =IFERROR(VLOOKUP($C6,MOSFET!$A$2:$Q$11,10,FALSE),"") -> 19.5 | T6: =IFERROR(VLOOKUP($B6,MOSFET!$A$2:$Q$11,11,FALSE),"") -> 18 | U6: =IFERROR(VLOOKUP($C6,MOSFET!$A$2:$Q$11,11,FALSE),"") -> 18 | V6: =IFERROR(VLOOKUP($B6,MOSFET!$A$2:$Q$11,12,FALSE),0) -> 0 | W6: =IFERROR(VLOOKUP($C6,MOSFET!$A$2:$Q$11,12,FALSE),0) -> 0 | X6: =IFERROR(VLOOKUP($B6,MOSFET!$A$2:$Q$11,13,FALSE),"") -> 70 | Y6: =IFERROR(VLOOKUP($C6,MOSFET!$A$2:$Q$11,13,FALSE),"") -> 81 | Z6: =IFERROR(VLOOKUP($B6,MOSFET!$A$2:$Q$11,16,FALSE),"") -> 5.7 | AA6: =IFERROR(VLOOKUP($C6,MOSFET!$A$2:$Q$11,16,FALSE),"") -> 4.3 | AB6: =IFERROR(R6*SQRT(Config!$B$13/T6),"") -> 9.1666667 | AC6: =IFERROR(S6*SQRT(Config!$B$13/U6),"") -> 8.125 | AD6: =IFERROR((1/(2*PI()))*SQRT((1+AB6*Config!$B$12)/(Config!$B$14*0.000000001*L6*0.000000000001))/1000000,"") -> 167.01676 | AE6: =IFERROR((1/(2*PI()))*SQRT((1+AC6*Config!$B$12)/(Config!$B$14*0.000000001*M6*0.000000000001))/1000000,"") -> 147.82959 | AF6: =IFERROR((AB6*N6*Config!$B$12^2/L6)/(1+(2*PI()*AD6*1000000*N6*0.000000000001*Config!$B$12)^2),"") -> 9.0598092 | AG6: =IFERROR((AC6*O6*Config!$B$12^2/M6)/(1+(2*PI()*AE6*1000000*O6*0.000000000001*Config!$B$12)^2),"") -> 5.0212656 | AH6: =IF(AF6="","",MAX(0,Config!$B$16*AF6-V6-Config!$B$15)) -> 12.683733 | AI6: =IF(AG6="","",MAX(0,Config!$B$16*AG6-W6-Config!$B$15)) -> 7.0297718 | AJ6: =IF(AH6="","",IF(AH6<=10,10,IF(AH6>=10000,10000,IF(VLOOKUP(AH6,Notes!$F$2:$G$74,1,TRUE)=AH6,AH6,VLOOKUP(AH6,Notes!$F$2:$G$74,2,TRUE))))) -> 13 | AK6: =IF(AI6="","",IF(AI6<=10,10,IF(AI6>=10000,10000,IF(VLOOKUP(AI6,Notes!$F$2:$G$74,1,TRUE)=AI6,AI6,VLOOKUP(AI6,Notes!$F$2:$G$74,2,TRUE))))) -> 10 | AL6: =IFERROR(1/(2*PI()*AJ6*L6*0.000000000001)/1000000,"") -> 5.4411946 | AM6: =IFERROR(1/(2*PI()*AK6*M6*0.000000000001)/1000000,"") -> 6.2413703 | AN6: =IF(OR(AL6="",AM6=""),"",MIN(AL6,AM6)) -> 5.4411946 | AO6: =IFERROR(1/(2*PI()*AN6*1000000*L6*0.000000000001),"") -> 13 | AP6: =IFERROR(1/(2*PI()*AN6*1000000*M6*0.000000000001),"") -> 11.470588 | AQ6: =IF(AO6="","",IF(MAX(AH6,AO6)<=10,10,IF(MAX(AH6,AO6)>=10000,10000,IF(VLOOKUP(MAX(AH6,AO6),Notes!$F$2:$G$74,1,TRUE)=MAX(AH6,AO6),MAX(AH6,AO6),VLOOKUP(MAX(AH6,AO6),Notes!$F$2:$G$74,2,TRUE))))) -> 13 | AR6: =IF(AP6="","",IF(MAX(AI6,AP6)<=10,10,IF(MAX(AI6,AP6)>=10000,10000,IF(VLOOKUP(MAX(AI6,AP6),Notes!$F$2:$G$74,1,TRUE)=MAX(AI6,AP6),MAX(AI6,AP6),VLOOKUP(MAX(AI6,AP6),Notes!$F$2:$G$74,2,TRUE))))) -> 12 | AS6: =IFERROR(P6+(L6-P6)/(1+AB6*Config!$B$12),"") -> 119.0583 | AT6: =IFERROR(Q6+(M6-Q6)/(1+AC6*Config!$B$12),"") -> 146.9697 | AU6: =IFERROR(MAX(0,MIN(TAN(RADIANS(Config!$B$21))/(2*PI()*Config!$B$20*1000*AS6*0.000000000001)-V6-Config!$B$15,SQRT(10^(Config!$B$22/10)-1)/(2*PI()*Config!$B$20*1000*AS6*0.000000000001)-V6-Config!$B$15)),"") -> 1169.5324 | AV6: =IFERROR(MAX(0,MIN(TAN(RADIANS(Config!$B$21))/(2*PI()*Config!$B$20*1000*AT6*0.000000000001)-W6-Config!$B$15,SQRT(10^(Config!$B$22/10)-1)/(2*PI()*Config!$B$20*1000*AT6*0.000000000001)-W6-Config!$B$15)),"") -> 947.42342 | AW6: =IF(AU6="","",IF(AU6<10,"<10",IF(AU6>=10000,10000,VLOOKUP(AU6,Notes!$F$2:$G$74,1,TRUE)))) -> 1100 | AX6: =IF(AV6="","",IF(AV6<10,"<10",IF(AV6>=10000,10000,VLOOKUP(AV6,Notes!$F$2:$G$74,1,TRUE)))) -> 910 | AY6: =IFERROR(IF((IF(Config!$B$8="R14",Config!$B$9,Config!$B$9*CC6/CB6))<=10,10,IF((IF(Config!$B$8="R14",Config!$B$9,Config!$B$9*CC6/CB6))>=10000,10000,IF(ABS((IF(Config!$B$8="R14",Config!$B$9,Config!$B$9*CC6/CB6))-VLOOKUP((IF(Config!$B$8="R14",Config!$B$9,Config!$B$9*CC6/CB6)),Notes!$F$2:$G$74,1,TRUE))<=ABS(VLOOKUP((IF(Config!$B$8="R14",Config!$B$9,Config!$B$9*CC6/CB6)),Notes!$F$2:$G$74,2,TRUE)-(IF(Config!$B$8="R14",Config!$B$9,Config!$B$9*CC6/CB6))),VLOOKUP((IF(Config!$B$8="R14",Config!$B$9,Config!$B$9*CC6/CB6)),Notes!$F$2:$G$74,1,TRUE),VLOOKUP((IF(Config!$B$8="R14",Config!$B$9,Config!$B$9*CC6/CB6)),Notes!$F$2:$G$74,2,TRUE)))),"") -> 100 | AZ6: =IFERROR(IF((IF(Config!$B$8="R15",Config!$B$9,Config!$B$9*CB6/CC6))<=10,10,IF((IF(Config!$B$8="R15",Config!$B$9,Config!$B$9*CB6/CC6))>=10000,10000,IF(ABS((IF(Config!$B$8="R15",Config!$B$9,Config!$B$9*CB6/CC6))-VLOOKUP((IF(Config!$B$8="R15",Config!$B$9,Config!$B$9*CB6/CC6)),Notes!$F$2:$G$74,1,TRUE))<=ABS(VLOOKUP((IF(Config!$B$8="R15",Config!$B$9,Config!$B$9*CB6/CC6)),Notes!$F$2:$G$74,2,TRUE)-(IF(Config!$B$8="R15",Config!$B$9,Config!$B$9*CB6/CC6))),VLOOKUP((IF(Config!$B$8="R15",Config!$B$9,Config!$B$9*CB6/CC6)),Notes!$F$2:$G$74,1,TRUE),VLOOKUP((IF(Config!$B$8="R15",Config!$B$9,Config!$B$9*CB6/CC6)),Notes!$F$2:$G$74,2,TRUE)))),"") -> 91 | BA6: =IF(OR(AW6="<10",AX6="<10"),"NO",IF(AND(AY6>=AJ6,AY6<=AW6,AZ6>=AK6,AZ6<=AX6,ABS(1/(AY6*L6)-1/(AZ6*M6))/MIN(1/(AY6*L6),1/(AZ6*M6))<=Config!$B$19),"YES","NO")) -> YES | BB6: =IF(AND(D6="VALIDÉ / VALIDATED",E6>0,F6>0),E6,IF(BA6="YES",AY6,AQ6)) -> 47 | BC6: =IF(AND(D6="VALIDÉ / VALIDATED",E6>0,F6>0),F6,IF(BA6="YES",AZ6,AR6)) -> 47 | BD6: =IF(AND(D6="VALIDÉ / VALIDATED",E6>0,F6>0),_xlfn.CONCAT("TEST Q",17),IF(BA6="YES","CIBLE INITIALE","CALCUL THÉORIQUE INITIAL")) -> TEST Q17 | BE6: =IFERROR(ABS(BB6*CB6-BC6*CC6)/MIN(BB6*CB6,BC6*CC6),"") -> 0.13675214 | BF6: =IF(B6="","",IF(VLOOKUP(B6,MOSFET!$A$2:$Q$11,2,FALSE)<>"N","NON – canal",IF(H6<2*Config!$B$11*Config!$B$17,"NON – Vdss",IF(J6<Config!$B$13*Config!$B$18,"NON – Id",IF(L6>Config!$B$23,"NON – Ciss",IF(OR(L6="",P6="",X6="",BQ6="",R6="",T6="",Z6=""),"DONNÉES À COMPLÉTER","OK")))))) -> OK | BG6: =IF(C6="","",IF(VLOOKUP(C6,MOSFET!$A$2:$Q$11,2,FALSE)<>"P","NON – canal",IF(I6<2*Config!$B$11*Config!$B$17,"NON – Vdss",IF(K6<Config!$B$13*Config!$B$18,"NON – Id",IF(M6>Config!$B$23,"NON – Ciss",IF(OR(M6="",Q6="",Y6="",BR6="",S6="",U6="",AA6=""),"DONNÉES À COMPLÉTER","OK")))))) -> OK | BH6: =IF(OR(BF6<>"OK",BG6<>"OK"),"NON – aptitude MOSFET",IF(AND(D6="VALIDÉ / VALIDATED",E6>0,F6>0),_xlfn.CONCAT("OUI – Q",17," confirmé"),IF(BO6>=0.82,"OUI – paire prioritaire / test scope requis",IF(BO6>=0.74,"OUI – paire acceptable / test scope requis","À ÉVALUER – compatibilité faible")))) -> OUI – Q17 confirmé | BI6: =IFERROR((Config!$B$34*BY6+Config!$B$35*BZ6+Config!$B$36*CA6)/Config!$B$37,"") -> 0.86986228 | BJ6: =IFERROR(MIN(BQ6,BR6)/MAX(BQ6,BR6),"") -> 0.83333333 | BK6: =IFERROR(MIN(X6,Y6)/MAX(X6,Y6),"") -> 0.86419753 | BL6: =IFERROR(MIN(AB6,AC6)/MAX(AB6,AC6),"") -> 0.88636364 | BM6: =IFERROR(MIN(P6,Q6)/MAX(P6,Q6),"") -> 0.81818182 | BN6: =IFERROR(MIN(Z6,AA6)/MAX(Z6,AA6),"") -> 0.75438596 | BO6: =IFERROR((Config!$B$25*BI6+Config!$B$26*BJ6+Config!$B$27*BK6+Config!$B$28*BL6+Config!$B$29*BM6+Config!$B$30*BN6)/Config!$B$31,"") -> 0.8474663 | BP6: =IF(OR(BF6<>"OK",BG6<>"OK"),1,IF(BO6>=0.9,5,IF(BO6>=0.82,4,IF(BO6>=0.74,3,IF(BO6>=0.66,2,1))))) -> 4 | BQ6: =IFERROR(VLOOKUP($B6,MOSFET!$A$2:$Q$11,14,FALSE),"") -> 35 | BR6: =IFERROR(VLOOKUP($C6,MOSFET!$A$2:$Q$11,14,FALSE),"") -> 42 | BS6: =IFERROR(P6+(L6-P6)*(1-0),"") -> 2250 | BT6: =IFERROR(Q6+(M6-Q6)*(1-0),"") -> 2550 | BU6: =IFERROR(P6+(L6-P6)*(1-0.5),"") -> 1170 | BV6: =IFERROR(Q6+(M6-Q6)*(1-0.5),"") -> 1330 | BW6: =IFERROR(P6+(L6-P6)*(1-0.95),"") -> 198 | BX6: =IFERROR(Q6+(M6-Q6)*(1-0.95),"") -> 232 | BY6: =IFERROR(MIN(BS6,BT6)/MAX(BS6,BT6),"") -> 0.88235294 | BZ6: =IFERROR(MIN(BU6,BV6)/MAX(BU6,BV6),"") -> 0.87969925 | CA6: =IFERROR(MIN(BW6,BX6)/MAX(BW6,BX6),"") -> 0.85344828 | CB6: =IFERROR(P6+(L6-P6)*(1-Config!$B$39),"") -> 1170 | CC6: =IFERROR(Q6+(M6-Q6)*(1-Config!$B$39),"") -> 1330 | CD6: =IF(OR(BF6<>"OK",BG6<>"OK"),"X – INADAPTÉ",IF(AND(BI6>=Config!$B$42,CE6>=Config!$B$43,CF6=0),"A – TRÈS BON CANDIDAT",IF(AND(BI6>=Config!$B$44,CE6>=Config!$B$45,CF6=0),"B – BON CANDIDAT","C – À ÉTUDIER"))) -> A – TRÈS BON CANDIDAT | CE6: =IFERROR(MIN(AY6,AZ6)/MAX(AY6,AZ6),"") -> 0.91 | CF6: =--(BJ6<Config!$B$46)+--(BK6<Config!$B$47)+--(BL6<Config!$B$47)+--(BM6<Config!$B$47)+--(BN6<Config!$B$48) -> 0 | CG6: =IF(CF6=0,"Aucune",IF(BJ6<Config!$B$46,"Qgd; ","")&IF(BK6<Config!$B$47,"Qg; ","")&IF(BL6<Config!$B$47,"gm; ","")&IF(BM6<Config!$B$47,"Crss; ","")&IF(BN6<Config!$B$48,"VGS; ","")) -> Aucune | CH6: =IF(D6="VALIDÉ / VALIDATED",IF(AND(E6>0,F6>0),"VALIDÉ R14/R15","VALIDATION INCOMPLÈTE"),IF(D6="TESTÉ – À ÉVALUER / TESTED – TO REVIEW","TESTÉ – À ÉVALUER",IF(D6="REJETÉ / REJECTED","REJETÉ","NON TESTÉ"))) -> VALIDÉ R14/R15
A7: S4 | B7: IXTQ36N30P | C7: IXTQ36P15P | D7: =IFERROR(VLOOKUP(A7,Selection!$A$17:$I$28,4,FALSE),"NON TESTÉ / NOT TESTED") -> NON TESTÉ / NOT TESTED | E7: =IFERROR(VLOOKUP(A7,Selection!$A$17:$I$28,5,FALSE),"") -> 0 | F7: =IFERROR(VLOOKUP(A7,Selection!$A$17:$I$28,6,FALSE),"") -> 0 | G7: =IF(Config!$B$3="FR",IFERROR(T(VLOOKUP(A7,Selection!$A$17:$I$28,7,FALSE)),""),IF(IFERROR(T(VLOOKUP(A7,Selection!$A$17:$I$28,8,FALSE)),"")<>"",IFERROR(T(VLOOKUP(A7,Selection!$A$17:$I$28,8,FALSE)),""),IFERROR(T(VLOOKUP(A7,Selection!$A$17:$I$28,7,FALSE)),""))) -> Combination to validate on Q17. | H7: =IFERROR(VLOOKUP($B7,MOSFET!$A$2:$Q$11,5,FALSE),"") -> 300 | I7: =IFERROR(VLOOKUP($C7,MOSFET!$A$2:$Q$11,5,FALSE),"") -> 150 | J7: =IFERROR(VLOOKUP($B7,MOSFET!$A$2:$Q$11,6,FALSE),"") -> 36 | K7: =IFERROR(VLOOKUP($C7,MOSFET!$A$2:$Q$11,6,FALSE),"") -> 36 | L7: =IFERROR(VLOOKUP($B7,MOSFET!$A$2:$Q$11,7,FALSE),"") -> 2250 | M7: =IFERROR(VLOOKUP($C7,MOSFET!$A$2:$Q$11,7,FALSE),"") -> 3100 | N7: =IFERROR(VLOOKUP($B7,MOSFET!$A$2:$Q$11,8,FALSE),"") -> 370 | O7: =IFERROR(VLOOKUP($C7,MOSFET!$A$2:$Q$11,8,FALSE),"") -> 610 | P7: =IFERROR(VLOOKUP($B7,MOSFET!$A$2:$Q$11,9,FALSE),"") -> 90 | Q7: =IFERROR(VLOOKUP($C7,MOSFET!$A$2:$Q$11,9,FALSE),"") -> 100 | R7: =IFERROR(VLOOKUP($B7,MOSFET!$A$2:$Q$11,10,FALSE),"") -> 22 | S7: =IFERROR(VLOOKUP($C7,MOSFET!$A$2:$Q$11,10,FALSE),"") -> 19 | T7: =IFERROR(VLOOKUP($B7,MOSFET!$A$2:$Q$11,11,FALSE),"") -> 18 | U7: =IFERROR(VLOOKUP($C7,MOSFET!$A$2:$Q$11,11,FALSE),"") -> 18 | V7: =IFERROR(VLOOKUP($B7,MOSFET!$A$2:$Q$11,12,FALSE),0) -> 0 | W7: =IFERROR(VLOOKUP($C7,MOSFET!$A$2:$Q$11,12,FALSE),0) -> 0 | X7: =IFERROR(VLOOKUP($B7,MOSFET!$A$2:$Q$11,13,FALSE),"") -> 70 | Y7: =IFERROR(VLOOKUP($C7,MOSFET!$A$2:$Q$11,13,FALSE),"") -> 55 | Z7: =IFERROR(VLOOKUP($B7,MOSFET!$A$2:$Q$11,16,FALSE),"") -> 5.7 | AA7: =IFERROR(VLOOKUP($C7,MOSFET!$A$2:$Q$11,16,FALSE),"") -> 4.8 | AB7: =IFERROR(R7*SQRT(Config!$B$13/T7),"") -> 9.1666667 | AC7: =IFERROR(S7*SQRT(Config!$B$13/U7),"") -> 7.9166667 | AD7: =IFERROR((1/(2*PI()))*SQRT((1+AB7*Config!$B$12)/(Config!$B$14*0.000000001*L7*0.000000000001))/1000000,"") -> 167.01676 | AE7: =IFERROR((1/(2*PI()))*SQRT((1+AC7*Config!$B$12)/(Config!$B$14*0.000000001*M7*0.000000000001))/1000000,"") -> 132.37217 | AF7: =IFERROR((AB7*N7*Config!$B$12^2/L7)/(1+(2*PI()*AD7*1000000*N7*0.000000000001*Config!$B$12)^2),"") -> 9.0598092 | AG7: =IFERROR((AC7*O7*Config!$B$12^2/M7)/(1+(2*PI()*AE7*1000000*O7*0.000000000001*Config!$B$12)^2),"") -> 5.7056364 | AH7: =IF(AF7="","",MAX(0,Config!$B$16*AF7-V7-Config!$B$15)) -> 12.683733 | AI7: =IF(AG7="","",MAX(0,Config!$B$16*AG7-W7-Config!$B$15)) -> 7.987891 | AJ7: =IF(AH7="","",IF(AH7<=10,10,IF(AH7>=10000,10000,IF(VLOOKUP(AH7,Notes!$F$2:$G$74,1,TRUE)=AH7,AH7,VLOOKUP(AH7,Notes!$F$2:$G$74,2,TRUE))))) -> 13 | AK7: =IF(AI7="","",IF(AI7<=10,10,IF(AI7>=10000,10000,IF(VLOOKUP(AI7,Notes!$F$2:$G$74,1,TRUE)=AI7,AI7,VLOOKUP(AI7,Notes!$F$2:$G$74,2,TRUE))))) -> 10 | AL7: =IFERROR(1/(2*PI()*AJ7*L7*0.000000000001)/1000000,"") -> 5.4411946 | AM7: =IFERROR(1/(2*PI()*AK7*M7*0.000000000001)/1000000,"") -> 5.1340304 | AN7: =IF(OR(AL7="",AM7=""),"",MIN(AL7,AM7)) -> 5.1340304 | AO7: =IFERROR(1/(2*PI()*AN7*1000000*L7*0.000000000001),"") -> 13.777778 | AP7: =IFERROR(1/(2*PI()*AN7*1000000*M7*0.000000000001),"") -> 10 | AQ7: =IF(AO7="","",IF(MAX(AH7,AO7)<=10,10,IF(MAX(AH7,AO7)>=10000,10000,IF(VLOOKUP(MAX(AH7,AO7),Notes!$F$2:$G$74,1,TRUE)=MAX(AH7,AO7),MAX(AH7,AO7),VLOOKUP(MAX(AH7,AO7),Notes!$F$2:$G$74,2,TRUE))))) -> 15 | AR7: =IF(AP7="","",IF(MAX(AI7,AP7)<=10,10,IF(MAX(AI7,AP7)>=10000,10000,IF(VLOOKUP(MAX(AI7,AP7),Notes!$F$2:$G$74,1,TRUE)=MAX(AI7,AP7),MAX(AI7,AP7),VLOOKUP(MAX(AI7,AP7),Notes!$F$2:$G$74,2,TRUE))))) -> 10 | AS7: =IFERROR(P7+(L7-P7)/(1+AB7*Config!$B$12),"") -> 119.0583 | AT7: =IFERROR(Q7+(M7-Q7)/(1+AC7*Config!$B$12),"") -> 146.63212 | AU7: =IFERROR(MAX(0,MIN(TAN(RADIANS(Config!$B$21))/(2*PI()*Config!$B$20*1000*AS7*0.000000000001)-V7-Config!$B$15,SQRT(10^(Config!$B$22/10)-1)/(2*PI()*Config!$B$20*1000*AS7*0.000000000001)-V7-Config!$B$15)),"") -> 1169.5324 | AV7: =IFERROR(MAX(0,MIN(TAN(RADIANS(Config!$B$21))/(2*PI()*Config!$B$20*1000*AT7*0.000000000001)-W7-Config!$B$15,SQRT(10^(Config!$B$22/10)-1)/(2*PI()*Config!$B$20*1000*AT7*0.000000000001)-W7-Config!$B$15)),"") -> 949.60455 | AW7: =IF(AU7="","",IF(AU7<10,"<10",IF(AU7>=10000,10000,VLOOKUP(AU7,Notes!$F$2:$G$74,1,TRUE)))) -> 1100 | AX7: =IF(AV7="","",IF(AV7<10,"<10",IF(AV7>=10000,10000,VLOOKUP(AV7,Notes!$F$2:$G$74,1,TRUE)))) -> 910 | AY7: =IFERROR(IF((IF(Config!$B$8="R14",Config!$B$9,Config!$B$9*CC7/CB7))<=10,10,IF((IF(Config!$B$8="R14",Config!$B$9,Config!$B$9*CC7/CB7))>=10000,10000,IF(ABS((IF(Config!$B$8="R14",Config!$B$9,Config!$B$9*CC7/CB7))-VLOOKUP((IF(Config!$B$8="R14",Config!$B$9,Config!$B$9*CC7/CB7)),Notes!$F$2:$G$74,1,TRUE))<=ABS(VLOOKUP((IF(Config!$B$8="R14",Config!$B$9,Config!$B$9*CC7/CB7)),Notes!$F$2:$G$74,2,TRUE)-(IF(Config!$B$8="R14",Config!$B$9,Config!$B$9*CC7/CB7))),VLOOKUP((IF(Config!$B$8="R14",Config!$B$9,Config!$B$9*CC7/CB7)),Notes!$F$2:$G$74,1,TRUE),VLOOKUP((IF(Config!$B$8="R14",Config!$B$9,Config!$B$9*CC7/CB7)),Notes!$F$2:$G$74,2,TRUE)))),"") -> 100 | AZ7: =IFERROR(IF((IF(Config!$B$8="R15",Config!$B$9,Config!$B$9*CB7/CC7))<=10,10,IF((IF(Config!$B$8="R15",Config!$B$9,Config!$B$9*CB7/CC7))>=10000,10000,IF(ABS((IF(Config!$B$8="R15",Config!$B$9,Config!$B$9*CB7/CC7))-VLOOKUP((IF(Config!$B$8="R15",Config!$B$9,Config!$B$9*CB7/CC7)),Notes!$F$2:$G$74,1,TRUE))<=ABS(VLOOKUP((IF(Config!$B$8="R15",Config!$B$9,Config!$B$9*CB7/CC7)),Notes!$F$2:$G$74,2,TRUE)-(IF(Config!$B$8="R15",Config!$B$9,Config!$B$9*CB7/CC7))),VLOOKUP((IF(Config!$B$8="R15",Config!$B$9,Config!$B$9*CB7/CC7)),Notes!$F$2:$G$74,1,TRUE),VLOOKUP((IF(Config!$B$8="R15",Config!$B$9,Config!$B$9*CB7/CC7)),Notes!$F$2:$G$74,2,TRUE)))),"") -> 75 | BA7: =IF(OR(AW7="<10",AX7="<10"),"NO",IF(AND(AY7>=AJ7,AY7<=AW7,AZ7>=AK7,AZ7<=AX7,ABS(1/(AY7*L7)-1/(AZ7*M7))/MIN(1/(AY7*L7),1/(AZ7*M7))<=Config!$B$19),"YES","NO")) -> YES | BB7: =IF(AND(D7="VALIDÉ / VALIDATED",E7>0,F7>0),E7,IF(BA7="YES",AY7,AQ7)) -> 100 | BC7: =IF(AND(D7="VALIDÉ / VALIDATED",E7>0,F7>0),F7,IF(BA7="YES",AZ7,AR7)) -> 75 | BD7: =IF(AND(D7="VALIDÉ / VALIDATED",E7>0,F7>0),_xlfn.CONCAT("TEST Q",17),IF(BA7="YES","CIBLE INITIALE","CALCUL THÉORIQUE INITIAL")) -> CIBLE INITIALE | BE7: =IFERROR(ABS(BB7*CB7-BC7*CC7)/MIN(BB7*CB7,BC7*CC7),"") -> 0.025641026 | BF7: =IF(B7="","",IF(VLOOKUP(B7,MOSFET!$A$2:$Q$11,2,FALSE)<>"N","NON – canal",IF(H7<2*Config!$B$11*Config!$B$17,"NON – Vdss",IF(J7<Config!$B$13*Config!$B$18,"NON – Id",IF(L7>Config!$B$23,"NON – Ciss",IF(OR(L7="",P7="",X7="",BQ7="",R7="",T7="",Z7=""),"DONNÉES À COMPLÉTER","OK")))))) -> OK | BG7: =IF(C7="","",IF(VLOOKUP(C7,MOSFET!$A$2:$Q$11,2,FALSE)<>"P","NON – canal",IF(I7<2*Config!$B$11*Config!$B$17,"NON – Vdss",IF(K7<Config!$B$13*Config!$B$18,"NON – Id",IF(M7>Config!$B$23,"NON – Ciss",IF(OR(M7="",Q7="",Y7="",BR7="",S7="",U7="",AA7=""),"DONNÉES À COMPLÉTER","OK")))))) -> OK | BH7: =IF(OR(BF7<>"OK",BG7<>"OK"),"NON – aptitude MOSFET",IF(AND(D7="VALIDÉ / VALIDATED",E7>0,F7>0),_xlfn.CONCAT("OUI – Q",17," confirmé"),IF(BO7>=0.82,"OUI – paire prioritaire / test scope requis",IF(BO7>=0.74,"OUI – paire acceptable / test scope requis","À ÉVALUER – compatibilité faible")))) -> OUI – paire acceptable / test scope requis | BI7: =IFERROR((Config!$B$34*BY7+Config!$B$35*BZ7+Config!$B$36*CA7)/Config!$B$37,"") -> 0.75418911 | BJ7: =IFERROR(MIN(BQ7,BR7)/MAX(BQ7,BR7),"") -> 0.51428571 | BK7: =IFERROR(MIN(X7,Y7)/MAX(X7,Y7),"") -> 0.78571429 | BL7: =IFERROR(MIN(AB7,AC7)/MAX(AB7,AC7),"") -> 0.86363636 | BM7: =IFERROR(MIN(P7,Q7)/MAX(P7,Q7),"") -> 0.9 | BN7: =IFERROR(MIN(Z7,AA7)/MAX(Z7,AA7),"") -> 0.84210526 | BO7: =IFERROR((Config!$B$25*BI7+Config!$B$26*BJ7+Config!$B$27*BK7+Config!$B$28*BL7+Config!$B$29*BM7+Config!$B$30*BN7)/Config!$B$31,"") -> 0.750727 | BP7: =IF(OR(BF7<>"OK",BG7<>"OK"),1,IF(BO7>=0.9,5,IF(BO7>=0.82,4,IF(BO7>=0.74,3,IF(BO7>=0.66,2,1))))) -> 3 | BQ7: =IFERROR(VLOOKUP($B7,MOSFET!$A$2:$Q$11,14,FALSE),"") -> 35 | BR7: =IFERROR(VLOOKUP($C7,MOSFET!$A$2:$Q$11,14,FALSE),"") -> 18 | BS7: =IFERROR(P7+(L7-P7)*(1-0),"") -> 2250 | BT7: =IFERROR(Q7+(M7-Q7)*(1-0),"") -> 3100 | BU7: =IFERROR(P7+(L7-P7)*(1-0.5),"") -> 1170 | BV7: =IFERROR(Q7+(M7-Q7)*(1-0.5),"") -> 1600 | BW7: =IFERROR(P7+(L7-P7)*(1-0.95),"") -> 198 | BX7: =IFERROR(Q7+(M7-Q7)*(1-0.95),"") -> 250 | BY7: =IFERROR(MIN(BS7,BT7)/MAX(BS7,BT7),"") -> 0.72580645 | BZ7: =IFERROR(MIN(BU7,BV7)/MAX(BU7,BV7),"") -> 0.73125 | CA7: =IFERROR(MIN(BW7,BX7)/MAX(BW7,BX7),"") -> 0.792 | CB7: =IFERROR(P7+(L7-P7)*(1-Config!$B$39),"") -> 1170 | CC7: =IFERROR(Q7+(M7-Q7)*(1-Config!$B$39),"") -> 1600 | CD7: =IF(OR(BF7<>"OK",BG7<>"OK"),"X – INADAPTÉ",IF(AND(BI7>=Config!$B$42,CE7>=Config!$B$43,CF7=0),"A – TRÈS BON CANDIDAT",IF(AND(BI7>=Config!$B$44,CE7>=Config!$B$45,CF7=0),"B – BON CANDIDAT","C – À ÉTUDIER"))) -> C – À ÉTUDIER | CE7: =IFERROR(MIN(AY7,AZ7)/MAX(AY7,AZ7),"") -> 0.75 | CF7: =--(BJ7<Config!$B$46)+--(BK7<Config!$B$47)+--(BL7<Config!$B$47)+--(BM7<Config!$B$47)+--(BN7<Config!$B$48) -> 0 | CG7: =IF(CF7=0,"Aucune",IF(BJ7<Config!$B$46,"Qgd; ","")&IF(BK7<Config!$B$47,"Qg; ","")&IF(BL7<Config!$B$47,"gm; ","")&IF(BM7<Config!$B$47,"Crss; ","")&IF(BN7<Config!$B$48,"VGS; ","")) -> Aucune | CH7: =IF(D7="VALIDÉ / VALIDATED",IF(AND(E7>0,F7>0),"VALIDÉ R14/R15","VALIDATION INCOMPLÈTE"),IF(D7="TESTÉ – À ÉVALUER / TESTED – TO REVIEW","TESTÉ – À ÉVALUER",IF(D7="REJETÉ / REJECTED","REJETÉ","NON TESTÉ"))) -> NON TESTÉ
