Workbook

Sheet Config
A1: Q17 Q5/Q6 — MOSFET Compatibility Configuration
A2: Compatibility-only model for the Q17 Q5/Q6 Class-A driver/error path. R7 = 100 Ω and R8 = 100 Ω are fixed implementation values; this workbook never calculates alternate resistor values.
A4: GENERAL
A5: Workbook version | B5: 1.0b9 | D5: New workbook derived from Q17_Q5-Q6_R7-R8_Rgate_Calculator_1.0b11.
A6: Release date | B6: 46303 | D6: Current release date.
A8: FIXED Q17 GATE RESISTORS
A9: R7 fixed value | B9: 100 | C9: Ω | D9: Hard value; not optimized.
A10: R8 fixed value | B10: 100 | C10: Ω | D10: Hard value; not optimized.
A12: Q17 OPERATING POINT
A13: Rail magnitude | B13: 50 | C13: V | D13: Reference rail magnitude.
A14: Q5/Q6 standing current | B14: 0.0771 | C14: A | D14: ≈632 mV / 8.2 Ω from project data.
A15: Nominal Q5/Q6 VDS | B15: 36 | C15: V | D15: Editable modeling value.
A16: Target case temperature | B16: 70 | C16: °C | D16: Thermal sanity-check assumption.
A18: HARD ELIGIBILITY SCREENS
A19: Minimum |Vdss| | B19: 150 | C19: V | D19: Hard Q17 engineering screen.
A20: Id safety factor | B20: 5 | C20: × Iq | D20: Idmax must be at least Iq × factor.
A21: Minimum thermal margin | B21: 30 | C21: °C | D21: Hard thermal sanity screen.
A22: Thermal full-score margin | B22: 60 | C22: °C | D22: Ranking normalization only.
A24: ROLE-SPECIFIC BASELINES — CURRENT Q17 IMPLEMENTATION
A25: Parameter | B25: Q5 baseline | C25: Q6 baseline | D25: Use
A26: Ciss (pF) | B26: 590 | C26: 543 | D26: Absolute gate-load burden; lower/equal to baseline receives full score.
A27: Qg (nC) | B27: 19 | C27: 13 | D27: Absolute gate-charge burden.
A28: Qgd (nC) | B28: 9.5 | C28: 5.8 | D28: Absolute Miller-charge burden.
A29: Crss (pF) | B29: 25 | C29: 5.5 | D29: Absolute reverse-transfer capacitance burden.
A30: Coss (pF) | B30: 140 | C30: 54 | D30: Absolute output-capacitance burden.
A32: INDIVIDUAL DEVICE SUITABILITY WEIGHTS
A33: Ciss burden | B33: 0.35 | D33: Role-specific baseline ratio.
A34: Qg burden | B34: 0.15 | D34: Role-specific baseline ratio.
A35: Qgd burden | B35: 0.1 | D35: Role-specific baseline ratio.
A36: Crss burden | B36: 0.05 | D36: Role-specific baseline ratio.
A37: Coss burden | B37: 0.05 | D37: Role-specific baseline ratio.
A38: Thermal headroom | B38: 0.2 | D38: min(1, thermal margin / full-score margin).
A39: Implementation / insulation | B39: 0.1 | D39: 1.00 insulated; 0.90 non-insulated.
A40: Weight total | B40: =SUM(B33:B39) -> 1 | D40: Must equal 100%.
A42: PAIR DYNAMIC-BALANCE WEIGHTS WITH R7 = R8 = 100 Ω
A43: Fixed-100 Ω pole / Ciss symmetry | B43: 0.7 | D43: Dominant pair-balance term because R7 and R8 are fixed equal.
A44: Qg similarity | B44: 0.15 | D44: Secondary pairwise dynamic indicator.
A45: Qgd similarity | B45: 0.15 | D45: Secondary Miller-charge indicator.
A46: Weight total | B46: =SUM(B43:B45) -> 1 | D46: Must equal 100%.
A48: OVERALL COMPATIBILITY MODEL
...

Sheet Selection
A1: Q5/Q6 MOSFET Compatibility — Q17
A2: Select Q5/Q6 for the real Q17 driver/error role. R7 = 100 Ω and R8 = 100 Ω are fixed. | G2: Version | H2: 1.0b9
G3: Date | H3: 46303
A4: PAIR SELECTION / SÉLECTION DU COUPLE
A5: MOSFET pair / Couple MOSFET | B5: FQPF7P20 / FQPF3N80C | G5: Pair ID | H5: =IFERROR(VLOOKUP(B5,Notes!$J$2:$K$7,2,FALSE),"") -> P8
A7: FIXED Q17 IMPLEMENTATION
A8: Position | B8: MOSFET | C8: Fixed resistor | D8: Value | E8: Test evidence | F8: Bench result | G8: Status | H8: Availability
A9: Q5 P | B9: =IFERROR(VLOOKUP($H$5,Calculations!$A$5:$AM$10,2,FALSE),"") -> FQPF7P20 | C9: R7 | D9: 100 | E9: =IFERROR(VLOOKUP($H$5,Calculations!$A$5:$AM$10,5,FALSE),"") -> TESTED | F9: =IFERROR(VLOOKUP($H$5,Calculations!$A$5:$AM$10,6,FALSE),"") -> PASS | G9: =IFERROR(VLOOKUP($H$5,Calculations!$A$5:$AM$10,39,FALSE),"") -> VALIDATED | H9: =IFERROR(VLOOKUP($H$5,Calculations!$A$5:$AM$10,4,FALSE),"") -> CURRENT
A10: Q6 N | B10: =IFERROR(VLOOKUP($H$5,Calculations!$A$5:$AM$10,3,FALSE),"") -> FQPF3N80C | C10: R8 | D10: 100 | E10: =IFERROR(VLOOKUP($H$5,Calculations!$A$5:$AM$10,5,FALSE),"") -> TESTED | F10: =IFERROR(VLOOKUP($H$5,Calculations!$A$5:$AM$10,6,FALSE),"") -> PASS | G10: =IFERROR(VLOOKUP($H$5,Calculations!$A$5:$AM$10,39,FALSE),"") -> VALIDATED | H10: =IFERROR(VLOOKUP($H$5,Calculations!$A$5:$AM$10,4,FALSE),"") -> CURRENT
A12: COMPATIBILITY SCORE
A13: Overall compatibility | B13: =IFERROR(VLOOKUP($H$5,Calculations!$A$5:$AM$10,36,FALSE),"") -> 0.96768956 | C13: Fit stars | D13: =IFERROR(VLOOKUP($H$5,Calculations!$A$5:$AM$10,37,FALSE),"") -> ***** | E13: Final Q17 stars | F13: =IFERROR(VLOOKUP($H$5,Calculations!$A$5:$AM$10,38,FALSE),"") -> ***** | G13: Availability | H13: =IFERROR(VLOOKUP($H$5,Calculations!$A$5:$AM$10,4,FALSE),"") -> CURRENT
A14: Q5 suitability | B14: =IFERROR(VLOOKUP($H$5,Calculations!$A$5:$AM$10,28,FALSE),"") -> 1 | C14: Q6 suitability | D14: =IFERROR(VLOOKUP($H$5,Calculations!$A$5:$AM$10,29,FALSE),"") -> 1 | E14: Pair balance | F14: =IFERROR(VLOOKUP($H$5,Calculations!$A$5:$AM$10,35,FALSE),"") -> 0.83844781 | G14: 100 Ω pole mismatch | H14: =IFERROR(VLOOKUP($H$5,Calculations!$A$5:$AM$10,34,FALSE),"") -> 0.086556169
A15: Fixed R7 | B15: 100 | C15: Fixed R8 | D15: 100 | E15: Hard-screen status | F15: =IF(AND(VLOOKUP($H$5,Calculations!$A$5:$AM$10,15,FALSE)="OK",VLOOKUP($H$5,Calculations!$A$5:$AM$10,16,FALSE)="OK",VLOOKUP($H$5,Calculations!$A$5:$AM$10,17,FALSE)="OK"),"PASS","FAIL") -> PASS | G15: Test / bench | H15: =VLOOKUP($H$5,Calculations!$A$5:$AM$10,5,FALSE)&" / "&VLOOKUP($H$5,Calculations!$A$5:$AM$10,6,FALSE) -> TESTED / PASS
A17: KEY DEVICE DATA
A18: Parameter | B18: Q5 | C18: Q6 | D18: Interpretation
A19: Ciss (pF) | B19: =VLOOKUP($H$5,Calculations!$A$5:$AM$10,18,FALSE) -> 590 | C19: =VLOOKUP($H$5,Calculations!$A$5:$AM$10,19,FALSE) -> 543 | D19: Absolute gate-load burden and fixed-100 Ω pole balance.
A20: Qg / Qgd (nC) | B20: =TEXT(VLOOKUP($H$5,Calculations!$A$5:$AM$10,20,FALSE),"0.0")&" / "&TEXT(VLOOKUP($H$5,Calculations!$A$5:$AM$10,22,FALSE),"0.0") -> 1.9 / 1.0 | C20: =TEXT(VLOOKUP($H$5,Calculations!$A$5:$AM$10,21,FALSE),"0.0")&" / "&TEXT(VLOOKUP($H$5,Calculations!$A$5:$AM$10,23,FALSE),"0.0") -> 1.3 / 0.6 | D20: Absolute drive burden; pair similarity is secondary.
A21: Crss / Coss (pF) | B21: =TEXT(VLOOKUP($H$5,Calculations!$A$5:$AM$10,24,FALSE),"0.0")&" / "&TEXT(VLOOKUP($H$5,Calculations!$A$5:$AM$10,26,FALSE),"0.0") -> 2.5 / 14.0 | C21: =TEXT(VLOOKUP($H$5,Calculations!$A$5:$AM$10,25,FALSE),"0.0")&" / "&TEXT(VLOOKUP($H$5,Calculations!$A$5:$AM$10,27,FALSE),"0.0") -> 0.6 / 5.4 | D21: Absolute parasitic-capacitance burden.
A22: Thermal margin (°C) | B22: =VLOOKUP($H$5,Calculations!$A$5:$AM$10,11,FALSE) -> 72.283832 | C22: =VLOOKUP($H$5,Calculations!$A$5:$AM$10,12,FALSE) -> 71.11808 | D22: Modeled sanity-check margin at the configured Q17 operating point.
A24: Q17 PHYSICAL TEST INPUT — FIXED R7 = R8 = 100 Ω
A25: MOSFET pair | B25: Pair ID | C25: Test evidence | D25: Bench result | E25: Test notes | F25: Status
A26: FQPF7P20 / FQPF3N80C | B26: P8 | C26: TESTED | D26: PASS | E26: Current Q17 physical test. | F26: =IF(C26="NOT TESTED","WAITING VALIDATION",IF(D26="PASS","VALIDATED",IF(D26="FAIL","NOT VALIDATED","WAITING VALIDATION"))) -> VALIDATED
A27: FQPF7P20 / FQP3N80C | B27: P7 | C27: NOT TESTED | D27: NOT TESTED | E27: Awaiting physical test. | F27: =IF(C27="NOT TESTED","WAITING VALIDATION",IF(D27="PASS","VALIDATED",IF(D27="FAIL","NOT VALIDATED","WAITING VALIDATION"))) -> WAITING VALIDATION
A28: IRFI9620GPBF / IRFI620GPBF | B28: P21 | C28: NOT TESTED | D28: NOT TESTED | E28: Awaiting physical test. | F28: =IF(C28="NOT TESTED","WAITING VALIDATION",IF(D28="PASS","VALIDATED",IF(D28="FAIL","NOT VALIDATED","WAITING VALIDATION"))) -> WAITING VALIDATION
A29: FQPF7P20 / FQPF4N90C | B29: P10 | C29: TESTED | D29: NOT TESTED | E29: Awaiting physical test. | F29: =IF(C29="NOT TESTED","WAITING VALIDATION",IF(D29="PASS","VALIDATED",IF(D29="FAIL","NOT VALIDATED","WAITING VALIDATION"))) -> WAITING VALIDATION
A30: IRFI9630GPBF / IRFI630GPBF | B30: P22 | C30: NOT TESTED | D30: NOT TESTED | E30: Awaiting physical test. | F30: =IF(C30="NOT TESTED","WAITING VALIDATION",IF(D30="PASS","VALIDATED",IF(D30="FAIL","NOT VALIDATED","WAITING VALIDATION"))) -> WAITING VALIDATION
A31: FQP3P20 / FQP3N30 | B31: P1 | C31: TESTED | D31: FAIL | E31: Historical Q17 physical test. | F31: =IF(C31="NOT TESTED","WAITING VALIDATION",IF(D31="PASS","VALIDATED",IF(D31="FAIL","NOT VALIDATED","WAITING VALIDATION"))) -> NOT VALIDATED
A32: Test evidence: NOT TESTED or TESTED. Bench result: NOT TESTED, PASS or FAIL. Status is automatic: NOT TESTED → WAITING VALIDATION; TESTED + PASS → VALIDATED; TESTED + FAIL → NOT VALIDATED.

Sheet Calculations
A1: Q5/Q6 MOSFET Compatibility — Q17 Pair Calculations
A2: R7 and R8 are fixed at 100 Ω. Q5 and Q6 are scored for their individual Q17 roles, then a smaller pair-balance term evaluates the fixed equal resistors.
A4: Pair | B4: Q5 P-channel | C4: Q6 N-channel | D4: Availability | E4: Test evidence | F4: Bench result | G4: Vdss P | H4: Vdss N | I4: Idmax P | J4: Idmax N | K4: Thermal margin P | L4: Thermal margin N | M4: Insulated P | N4: Insulated N | O4: Vdss screen | P4: Id screen | Q4: Thermal screen | R4: Ciss P | S4: Ciss N | T4: Qg P | U4: Qg N | V4: Qgd P | W4: Qgd N | X4: Crss P | Y4: Crss N | Z4: Coss P | AA4: Coss N | AB4: Q5 suitability | AC4: Q6 suitability | AD4: Fixed R7 (Ω) | AE4: Fixed R8 (Ω) | AF4: fQ5 @100Ω (MHz) | AG4: fQ6 @100Ω (MHz) | AH4: 100Ω pole mismatch | AI4: Pair balance | AJ4: Overall compatibility | AK4: Fit stars | AL4: Final Q17 stars | AM4: Status
A5: P8 | B5: FQPF7P20 | C5: FQPF3N80C | D5: =IF(OR(VLOOKUP(B5,MOSFET!$A$4:$Z$19,20,FALSE)="ARCHIVE",VLOOKUP(C5,MOSFET!$A$4:$Z$19,20,FALSE)="ARCHIVE"),"ARCHIVE",IF(OR(VLOOKUP(B5,MOSFET!$A$4:$Z$19,20,FALSE)="DATABASE",VLOOKUP(C5,MOSFET!$A$4:$Z$19,20,FALSE)="DATABASE"),"DATABASE","CURRENT")) -> CURRENT | E5: =IFERROR(VLOOKUP(A5,Selection!$B$26:$F$31,2,FALSE),"NOT TESTED") -> TESTED | F5: =IFERROR(VLOOKUP(A5,Selection!$B$26:$F$31,3,FALSE),"NOT TESTED") -> PASS | G5: =IFERROR(VLOOKUP(B5,MOSFET!$A$4:$Z$19,5,FALSE),"") -> 200 | H5: =IFERROR(VLOOKUP(C5,MOSFET!$A$4:$Z$19,5,FALSE),"") -> 800 | I5: =IFERROR(VLOOKUP(B5,MOSFET!$A$4:$Z$19,6,FALSE),"") -> 5.2 | J5: =IFERROR(VLOOKUP(C5,MOSFET!$A$4:$Z$19,6,FALSE),"") -> 3 | K5: =IFERROR(VLOOKUP(B5,MOSFET!$A$4:$Z$19,24,FALSE),"") -> 72.283832 | L5: =IFERROR(VLOOKUP(C5,MOSFET!$A$4:$Z$19,24,FALSE),"") -> 71.11808 | M5: =IFERROR(VLOOKUP(B5,MOSFET!$A$4:$Z$19,16,FALSE),"") -> YES | N5: =IFERROR(VLOOKUP(C5,MOSFET!$A$4:$Z$19,16,FALSE),"") -> YES | O5: =IF(MIN(G5,H5)>=Config!$B$19,"OK","FAIL") -> OK | P5: =IF(MIN(I5,J5)>=Config!$B$14*Config!$B$20,"OK","FAIL") -> OK | Q5: =IF(MIN(K5,L5)>=Config!$B$21,"OK","FAIL") -> OK | R5: =IFERROR(VLOOKUP(B5,MOSFET!$A$4:$Z$19,10,FALSE),"") -> 590 | S5: =IFERROR(VLOOKUP(C5,MOSFET!$A$4:$Z$19,10,FALSE),"") -> 543 | T5: =IFERROR(VLOOKUP(B5,MOSFET!$A$4:$Z$19,13,FALSE),"") -> 19 | U5: =IFERROR(VLOOKUP(C5,MOSFET!$A$4:$Z$19,13,FALSE),"") -> 13 | V5: =IFERROR(VLOOKUP(B5,MOSFET!$A$4:$Z$19,14,FALSE),"") -> 9.5 | W5: =IFERROR(VLOOKUP(C5,MOSFET!$A$4:$Z$19,14,FALSE),"") -> 5.8 | X5: =IFERROR(VLOOKUP(B5,MOSFET!$A$4:$Z$19,12,FALSE),"") -> 25 | Y5: =IFERROR(VLOOKUP(C5,MOSFET!$A$4:$Z$19,12,FALSE),"") -> 5.5 | Z5: =IFERROR(VLOOKUP(B5,MOSFET!$A$4:$Z$19,11,FALSE),"") -> 140 | AA5: =IFERROR(VLOOKUP(C5,MOSFET!$A$4:$Z$19,11,FALSE),"") -> 54 | AB5: =IFERROR(Config!$B$33*MIN(1,Config!$B$26/R5)+Config!$B$34*MIN(1,Config!$B$27/T5)+Config!$B$35*MIN(1,Config!$B$28/V5)+Config!$B$36*MIN(1,Config!$B$29/X5)+Config!$B$37*MIN(1,Config!$B$30/Z5)+Config!$B$38*MIN(1,K5/Config!$B$22)+Config!$B$39*IF(M5="YES",1,0.9),"") -> 1 | AC5: =IFERROR(Config!$B$33*MIN(1,Config!$C$26/S5)+Config!$B$34*MIN(1,Config!$C$27/U5)+Config!$B$35*MIN(1,Config!$C$28/W5)+Config!$B$36*MIN(1,Config!$C$29/Y5)+Config!$B$37*MIN(1,Config!$C$30/AA5)+Config!$B$38*MIN(1,L5/Config!$B$22)+Config!$B$39*IF(N5="YES",1,0.9),"") -> 1 | AD5: 100 | AE5: 100 | AF5: =IFERROR(1/(2*PI()*AD5*R5*0.000000000001)/1000000,"") -> 2.6975414 | AG5: =IFERROR(1/(2*PI()*AE5*S5*0.000000000001)/1000000,"") -> 2.9310303 | AH5: =IFERROR(ABS(AF5-AG5)/MIN(AF5,AG5),"") -> 0.086556169 | AI5: =IFERROR(Config!$B$43*MIN(R5,S5)/MAX(R5,S5)+Config!$B$44*MIN(T5,U5)/MAX(T5,U5)+Config!$B$45*MIN(V5,W5)/MAX(V5,W5),"") -> 0.83844781 | AJ5: =IF(OR(O5="FAIL",P5="FAIL",Q5="FAIL"),0,Config!$B$49*MIN(AB5,AC5)+Config!$B$50*AI5) -> 0.96768956 | AK5: =IF(AJ5>=Config!$B$55,"*****",IF(AJ5>=Config!$B$56,"****",IF(AJ5>=Config!$B$57,"***",IF(AJ5>=Config!$B$58,"**","*")))) -> ***** | AL5: =IF(OR(O5="FAIL",P5="FAIL",Q5="FAIL"),"*",IF(AND(E5="TESTED",F5="PASS",D5<>"ARCHIVE"),AK5,IF(LEN(AK5)>Config!$B$59,REPT("*",Config!$B$59),AK5))) -> ***** | AM5: =IF(OR(O5="FAIL",P5="FAIL",Q5="FAIL"),"NOT VALIDATED",IF(E5="NOT TESTED","WAITING VALIDATION",IF(F5="PASS","VALIDATED",IF(F5="FAIL","NOT VALIDATED","WAITING VALIDATION")))) -> VALIDATED
A6: P7 | B6: FQPF7P20 | C6: FQP3N80C | D6: =IF(OR(VLOOKUP(B6,MOSFET!$A$4:$Z$19,20,FALSE)="ARCHIVE",VLOOKUP(C6,MOSFET!$A$4:$Z$19,20,FALSE)="ARCHIVE"),"ARCHIVE",IF(OR(VLOOKUP(B6,MOSFET!$A$4:$Z$19,20,FALSE)="DATABASE",VLOOKUP(C6,MOSFET!$A$4:$Z$19,20,FALSE)="DATABASE"),"DATABASE","CURRENT")) -> CURRENT | E6: =IFERROR(VLOOKUP(A6,Selection!$B$26:$F$31,2,FALSE),"NOT TESTED") -> NOT TESTED | F6: =IFERROR(VLOOKUP(A6,Selection!$B$26:$F$31,3,FALSE),"NOT TESTED") -> NOT TESTED | G6: =IFERROR(VLOOKUP(B6,MOSFET!$A$4:$Z$19,5,FALSE),"") -> 200 | H6: =IFERROR(VLOOKUP(C6,MOSFET!$A$4:$Z$19,5,FALSE),"") -> 800 | I6: =IFERROR(VLOOKUP(B6,MOSFET!$A$4:$Z$19,6,FALSE),"") -> 5.2 | J6: =IFERROR(VLOOKUP(C6,MOSFET!$A$4:$Z$19,6,FALSE),"") -> 3 | K6: =IFERROR(VLOOKUP(B6,MOSFET!$A$4:$Z$19,24,FALSE),"") -> 72.283832 | L6: =IFERROR(VLOOKUP(C6,MOSFET!$A$4:$Z$19,24,FALSE),"") -> 76.752548 | M6: =IFERROR(VLOOKUP(B6,MOSFET!$A$4:$Z$19,16,FALSE),"") -> YES | N6: =IFERROR(VLOOKUP(C6,MOSFET!$A$4:$Z$19,16,FALSE),"") -> NO | O6: =IF(MIN(G6,H6)>=Config!$B$19,"OK","FAIL") -> OK | P6: =IF(MIN(I6,J6)>=Config!$B$14*Config!$B$20,"OK","FAIL") -> OK | Q6: =IF(MIN(K6,L6)>=Config!$B$21,"OK","FAIL") -> OK | R6: =IFERROR(VLOOKUP(B6,MOSFET!$A$4:$Z$19,10,FALSE),"") -> 590 | S6: =IFERROR(VLOOKUP(C6,MOSFET!$A$4:$Z$19,10,FALSE),"") -> 543 | T6: =IFERROR(VLOOKUP(B6,MOSFET!$A$4:$Z$19,13,FALSE),"") -> 19 | U6: =IFERROR(VLOOKUP(C6,MOSFET!$A$4:$Z$19,13,FALSE),"") -> 13 | V6: =IFERROR(VLOOKUP(B6,MOSFET!$A$4:$Z$19,14,FALSE),"") -> 9.5 | W6: =IFERROR(VLOOKUP(C6,MOSFET!$A$4:$Z$19,14,FALSE),"") -> 5.8 | X6: =IFERROR(VLOOKUP(B6,MOSFET!$A$4:$Z$19,12,FALSE),"") -> 25 | Y6: =IFERROR(VLOOKUP(C6,MOSFET!$A$4:$Z$19,12,FALSE),"") -> 5.5 | Z6: =IFERROR(VLOOKUP(B6,MOSFET!$A$4:$Z$19,11,FALSE),"") -> 140 | AA6: =IFERROR(VLOOKUP(C6,MOSFET!$A$4:$Z$19,11,FALSE),"") -> 54 | AB6: =IFERROR(Config!$B$33*MIN(1,Config!$B$26/R6)+Config!$B$34*MIN(1,Config!$B$27/T6)+Config!$B$35*MIN(1,Config!$B$28/V6)+Config!$B$36*MIN(1,Config!$B$29/X6)+Config!$B$37*MIN(1,Config!$B$30/Z6)+Config!$B$38*MIN(1,K6/Config!$B$22)+Config!$B$39*IF(M6="YES",1,0.9),"") -> 1 | AC6: =IFERROR(Config!$B$33*MIN(1,Config!$C$26/S6)+Config!$B$34*MIN(1,Config!$C$27/U6)+Config!$B$35*MIN(1,Config!$C$28/W6)+Config!$B$36*MIN(1,Config!$C$29/Y6)+Config!$B$37*MIN(1,Config!$C$30/AA6)+Config!$B$38*MIN(1,L6/Config!$B$22)+Config!$B$39*IF(N6="YES",1,0.9),"") -> 0.99 | AD6: 100 | AE6: 100 | AF6: =IFERROR(1/(2*PI()*AD6*R6*0.000000000001)/1000000,"") -> 2.6975414 | AG6: =IFERROR(1/(2*PI()*AE6*S6*0.000000000001)/1000000,"") -> 2.9310303 | AH6: =IFERROR(ABS(AF6-AG6)/MIN(AF6,AG6),"") -> 0.086556169 | AI6: =IFERROR(Config!$B$43*MIN(R6,S6)/MAX(R6,S6)+Config!$B$44*MIN(T6,U6)/MAX(T6,U6)+Config!$B$45*MIN(V6,W6)/MAX(V6,W6),"") -> 0.83844781 | AJ6: =IF(OR(O6="FAIL",P6="FAIL",Q6="FAIL"),0,Config!$B$49*MIN(AB6,AC6)+Config!$B$50*AI6) -> 0.95968956 | AK6: =IF(AJ6>=Config!$B$55,"*****",IF(AJ6>=Config!$B$56,"****",IF(AJ6>=Config!$B$57,"***",IF(AJ6>=Config!$B$58,"**","*")))) -> ***** | AL6: =IF(OR(O6="FAIL",P6="FAIL",Q6="FAIL"),"*",IF(AND(E6="TESTED",F6="PASS",D6<>"ARCHIVE"),AK6,IF(LEN(AK6)>Config!$B$59,REPT("*",Config!$B$59),AK6))) -> **** | AM6: =IF(OR(O6="FAIL",P6="FAIL",Q6="FAIL"),"NOT VALIDATED",IF(E6="NOT TESTED","WAITING VALIDATION",IF(F6="PASS","VALIDATED",IF(F6="FAIL","NOT VALIDATED","WAITING VALIDATION")))) -> WAITING VALIDATION
A7: P21 | B7: IRFI9620GPBF | C7: IRFI620GPBF | D7: =IF(OR(VLOOKUP(B7,MOSFET!$A$4:$Z$19,20,FALSE)="ARCHIVE",VLOOKUP(C7,MOSFET!$A$4:$Z$19,20,FALSE)="ARCHIVE"),"ARCHIVE",IF(OR(VLOOKUP(B7,MOSFET!$A$4:$Z$19,20,FALSE)="DATABASE",VLOOKUP(C7,MOSFET!$A$4:$Z$19,20,FALSE)="DATABASE"),"DATABASE","CURRENT")) -> CURRENT | E7: =IFERROR(VLOOKUP(A7,Selection!$B$26:$F$31,2,FALSE),"NOT TESTED") -> NOT TESTED | F7: =IFERROR(VLOOKUP(A7,Selection!$B$26:$F$31,3,FALSE),"NOT TESTED") -> NOT TESTED | G7: =IFERROR(VLOOKUP(B7,MOSFET!$A$4:$Z$19,5,FALSE),"") -> 200 | H7: =IFERROR(VLOOKUP(C7,MOSFET!$A$4:$Z$19,5,FALSE),"") -> 200 | I7: =IFERROR(VLOOKUP(B7,MOSFET!$A$4:$Z$19,6,FALSE),"") -> 3 | J7: =IFERROR(VLOOKUP(C7,MOSFET!$A$4:$Z$19,6,FALSE),"") -> 4.1 | K7: =IFERROR(VLOOKUP(B7,MOSFET!$A$4:$Z$19,24,FALSE),"") -> 93.62004 | L7: =IFERROR(VLOOKUP(C7,MOSFET!$A$4:$Z$19,24,FALSE),"") -> 68.62004 | M7: =IFERROR(VLOOKUP(B7,MOSFET!$A$4:$Z$19,16,FALSE),"") -> YES | N7: =IFERROR(VLOOKUP(C7,MOSFET!$A$4:$Z$19,16,FALSE),"") -> YES | O7: =IF(MIN(G7,H7)>=Config!$B$19,"OK","FAIL") -> OK | P7: =IF(MIN(I7,J7)>=Config!$B$14*Config!$B$20,"OK","FAIL") -> OK | Q7: =IF(MIN(K7,L7)>=Config!$B$21,"OK","FAIL") -> OK | R7: =IFERROR(VLOOKUP(B7,MOSFET!$A$4:$Z$19,10,FALSE),"") -> 340 | S7: =IFERROR(VLOOKUP(C7,MOSFET!$A$4:$Z$19,10,FALSE),"") -> 260 | T7: =IFERROR(VLOOKUP(B7,MOSFET!$A$4:$Z$19,13,FALSE),"") -> 15 | U7: =IFERROR(VLOOKUP(C7,MOSFET!$A$4:$Z$19,13,FALSE),"") -> 14 | V7: =IFERROR(VLOOKUP(B7,MOSFET!$A$4:$Z$19,14,FALSE),"") -> 8.4 | W7: =IFERROR(VLOOKUP(C7,MOSFET!$A$4:$Z$19,14,FALSE),"") -> 7.9 | X7: =IFERROR(VLOOKUP(B7,MOSFET!$A$4:$Z$19,12,FALSE),"") -> 33 | Y7: =IFERROR(VLOOKUP(C7,MOSFET!$A$4:$Z$19,12,FALSE),"") -> 30 | Z7: =IFERROR(VLOOKUP(B7,MOSFET!$A$4:$Z$19,11,FALSE),"") -> 110 | AA7: =IFERROR(VLOOKUP(C7,MOSFET!$A$4:$Z$19,11,FALSE),"") -> 100 | AB7: =IFERROR(Config!$B$33*MIN(1,Config!$B$26/R7)+Config!$B$34*MIN(1,Config!$B$27/T7)+Config!$B$35*MIN(1,Config!$B$28/V7)+Config!$B$36*MIN(1,Config!$B$29/X7)+Config!$B$37*MIN(1,Config!$B$30/Z7)+Config!$B$38*MIN(1,K7/Config!$B$22)+Config!$B$39*IF(M7="YES",1,0.9),"") -> 0.98787879 | AC7: =IFERROR(Config!$B$33*MIN(1,Config!$C$26/S7)+Config!$B$34*MIN(1,Config!$C$27/U7)+Config!$B$35*MIN(1,Config!$C$28/W7)+Config!$B$36*MIN(1,Config!$C$29/Y7)+Config!$B$37*MIN(1,Config!$C$30/AA7)+Config!$B$38*MIN(1,L7/Config!$B$22)+Config!$B$39*IF(N7="YES",1,0.9),"") -> 0.8988701 | AD7: 100 | AE7: 100 | AF7: =IFERROR(1/(2*PI()*AD7*R7*0.000000000001)/1000000,"") -> 4.6810277 | AG7: =IFERROR(1/(2*PI()*AE7*S7*0.000000000001)/1000000,"") -> 6.121344 | AH7: =IFERROR(ABS(AF7-AG7)/MIN(AF7,AG7),"") -> 0.30769231 | AI7: =IFERROR(Config!$B$43*MIN(R7,S7)/MAX(R7,S7)+Config!$B$44*MIN(T7,U7)/MAX(T7,U7)+Config!$B$45*MIN(V7,W7)/MAX(V7,W7),"") -> 0.81636555 | AJ7: =IF(OR(O7="FAIL",P7="FAIL",Q7="FAIL"),0,Config!$B$49*MIN(AB7,AC7)+Config!$B$50*AI7) -> 0.88236919 | AK7: =IF(AJ7>=Config!$B$55,"*****",IF(AJ7>=Config!$B$56,"****",IF(AJ7>=Config!$B$57,"***",IF(AJ7>=Config!$B$58,"**","*")))) -> **** | AL7: =IF(OR(O7="FAIL",P7="FAIL",Q7="FAIL"),"*",IF(AND(E7="TESTED",F7="PASS",D7<>"ARCHIVE"),AK7,IF(LEN(AK7)>Config!$B$59,REPT("*",Config!$B$59),AK7))) -> **** | AM7: =IF(OR(O7="FAIL",P7="FAIL",Q7="FAIL"),"NOT VALIDATED",IF(E7="NOT TESTED","WAITING VALIDATION",IF(F7="PASS","VALIDATED",IF(F7="FAIL","NOT VALIDATED","WAITING VALIDATION")))) -> WAITING VALIDATION
A8: P10 | B8: FQPF7P20 | C8: FQPF4N90C | D8: =IF(OR(VLOOKUP(B8,MOSFET!$A$4:$Z$19,20,FALSE)="ARCHIVE",VLOOKUP(C8,MOSFET!$A$4:$Z$19,20,FALSE)="ARCHIVE"),"ARCHIVE",IF(OR(VLOOKUP(B8,MOSFET!$A$4:$Z$19,20,FALSE)="DATABASE",VLOOKUP(C8,MOSFET!$A$4:$Z$19,20,FALSE)="DATABASE"),"DATABASE","CURRENT")) -> CURRENT | E8: =IFERROR(VLOOKUP(A8,Selection!$B$26:$F$31,2,FALSE),"NOT TESTED") -> TESTED | F8: =IFERROR(VLOOKUP(A8,Selection!$B$26:$F$31,3,FALSE),"NOT TESTED") -> NOT TESTED | G8: =IFERROR(VLOOKUP(B8,MOSFET!$A$4:$Z$19,5,FALSE),"") -> 200 | H8: =IFERROR(VLOOKUP(C8,MOSFET!$A$4:$Z$19,5,FALSE),"") -> 900 | I8: =IFERROR(VLOOKUP(B8,MOSFET!$A$4:$Z$19,6,FALSE),"") -> 5.2 | J8: =IFERROR(VLOOKUP(C8,MOSFET!$A$4:$Z$19,6,FALSE),"") -> 4 | K8: =IFERROR(VLOOKUP(B8,MOSFET!$A$4:$Z$19,24,FALSE),"") -> 72.283832 | L8: =IFERROR(VLOOKUP(C8,MOSFET!$A$4:$Z$19,24,FALSE),"") -> 72.616904 | M8: =IFERROR(VLOOKUP(B8,MOSFET!$A$4:$Z$19,16,FALSE),"") -> YES | N8: =IFERROR(VLOOKUP(C8,MOSFET!$A$4:$Z$19,16,FALSE),"") -> YES | O8: =IF(MIN(G8,H8)>=Config!$B$19,"OK","FAIL") -> OK | P8: =IF(MIN(I8,J8)>=Config!$B$14*Config!$B$20,"OK","FAIL") -> OK | Q8: =IF(MIN(K8,L8)>=Config!$B$21,"OK","FAIL") -> OK | R8: =IFERROR(VLOOKUP(B8,MOSFET!$A$4:$Z$19,10,FALSE),"") -> 590 | S8: =IFERROR(VLOOKUP(C8,MOSFET!$A$4:$Z$19,10,FALSE),"") -> 740 | T8: =IFERROR(VLOOKUP(B8,MOSFET!$A$4:$Z$19,13,FALSE),"") -> 19 | U8: =IFERROR(VLOOKUP(C8,MOSFET!$A$4:$Z$19,13,FALSE),"") -> 17 | V8: =IFERROR(VLOOKUP(B8,MOSFET!$A$4:$Z$19,14,FALSE),"") -> 9.5 | W8: =IFERROR(VLOOKUP(C8,MOSFET!$A$4:$Z$19,14,FALSE),"") -> 7.5 | X8: =IFERROR(VLOOKUP(B8,MOSFET!$A$4:$Z$19,12,FALSE),"") -> 25 | Y8: =IFERROR(VLOOKUP(C8,MOSFET!$A$4:$Z$19,12,FALSE),"") -> 5.6 | Z8: =IFERROR(VLOOKUP(B8,MOSFET!$A$4:$Z$19,11,FALSE),"") -> 140 | AA8: =IFERROR(VLOOKUP(C8,MOSFET!$A$4:$Z$19,11,FALSE),"") -> 65 | AB8: =IFERROR(Config!$B$33*MIN(1,Config!$B$26/R8)+Config!$B$34*MIN(1,Config!$B$27/T8)+Config!$B$35*MIN(1,Config!$B$28/V8)+Config!$B$36*MIN(1,Config!$B$29/X8)+Config!$B$37*MIN(1,Config!$B$30/Z8)+Config!$B$38*MIN(1,K8/Config!$B$22)+Config!$B$39*IF(M8="YES",1,0.9),"") -> 1 | AC8: =IFERROR(Config!$B$33*MIN(1,Config!$C$26/S8)+Config!$B$34*MIN(1,Config!$C$27/U8)+Config!$B$35*MIN(1,Config!$C$28/W8)+Config!$B$36*MIN(1,Config!$C$29/Y8)+Config!$B$37*MIN(1,Config!$C$30/AA8)+Config!$B$38*MIN(1,L8/Config!$B$22)+Config!$B$39*IF(N8="YES",1,0.9),"") -> 0.83950914 | AD8: 100 | AE8: 100 | AF8: =IFERROR(1/(2*PI()*AD8*R8*0.000000000001)/1000000,"") -> 2.6975414 | AG8: =IFERROR(1/(2*PI()*AE8*S8*0.000000000001)/1000000,"") -> 2.1507425 | AH8: =IFERROR(ABS(AF8-AG8)/MIN(AF8,AG8),"") -> 0.25423729 | AI8: =IFERROR(Config!$B$43*MIN(R8,S8)/MAX(R8,S8)+Config!$B$44*MIN(T8,U8)/MAX(T8,U8)+Config!$B$45*MIN(V8,W8)/MAX(V8,W8),"") -> 0.81073969 | AJ8: =IF(OR(O8="FAIL",P8="FAIL",Q8="FAIL"),0,Config!$B$49*MIN(AB8,AC8)+Config!$B$50*AI8) -> 0.83375525 | AK8: =IF(AJ8>=Config!$B$55,"*****",IF(AJ8>=Config!$B$56,"****",IF(AJ8>=Config!$B$57,"***",IF(AJ8>=Config!$B$58,"**","*")))) -> **** | AL8: =IF(OR(O8="FAIL",P8="FAIL",Q8="FAIL"),"*",IF(AND(E8="TESTED",F8="PASS",D8<>"ARCHIVE"),AK8,IF(LEN(AK8)>Config!$B$59,REPT("*",Config!$B$59),AK8))) -> **** | AM8: =IF(OR(O8="FAIL",P8="FAIL",Q8="FAIL"),"NOT VALIDATED",IF(E8="NOT TESTED","WAITING VALIDATION",IF(F8="PASS","VALIDATED",IF(F8="FAIL","NOT VALIDATED","WAITING VALIDATION")))) -> WAITING VALIDATION
A9: P22 | B9: IRFI9630GPBF | C9: IRFI630GPBF | D9: =IF(OR(VLOOKUP(B9,MOSFET!$A$4:$Z$19,20,FALSE)="ARCHIVE",VLOOKUP(C9,MOSFET!$A$4:$Z$19,20,FALSE)="ARCHIVE"),"ARCHIVE",IF(OR(VLOOKUP(B9,MOSFET!$A$4:$Z$19,20,FALSE)="DATABASE",VLOOKUP(C9,MOSFET!$A$4:$Z$19,20,FALSE)="DATABASE"),"DATABASE","CURRENT")) -> CURRENT | E9: =IFERROR(VLOOKUP(A9,Selection!$B$26:$F$31,2,FALSE),"NOT TESTED") -> NOT TESTED | F9: =IFERROR(VLOOKUP(A9,Selection!$B$26:$F$31,3,FALSE),"NOT TESTED") -> NOT TESTED | G9: =IFERROR(VLOOKUP(B9,MOSFET!$A$4:$Z$19,5,FALSE),"") -> 200 | H9: =IFERROR(VLOOKUP(C9,MOSFET!$A$4:$Z$19,5,FALSE),"") -> 200 | I9: =IFERROR(VLOOKUP(B9,MOSFET!$A$4:$Z$19,6,FALSE),"") -> 4.3 | J9: =IFERROR(VLOOKUP(C9,MOSFET!$A$4:$Z$19,6,FALSE),"") -> 5.9 | K9: =IFERROR(VLOOKUP(B9,MOSFET!$A$4:$Z$19,24,FALSE),"") -> 70.00784 | L9: =IFERROR(VLOOKUP(C9,MOSFET!$A$4:$Z$19,24,FALSE),"") -> 70.00784 | M9: =IFERROR(VLOOKUP(B9,MOSFET!$A$4:$Z$19,16,FALSE),"") -> YES | N9: =IFERROR(VLOOKUP(C9,MOSFET!$A$4:$Z$19,16,FALSE),"") -> YES | O9: =IF(MIN(G9,H9)>=Config!$B$19,"OK","FAIL") -> OK | P9: =IF(MIN(I9,J9)>=Config!$B$14*Config!$B$20,"OK","FAIL") -> OK | Q9: =IF(MIN(K9,L9)>=Config!$B$21,"OK","FAIL") -> OK | R9: =IFERROR(VLOOKUP(B9,MOSFET!$A$4:$Z$19,10,FALSE),"") -> 700 | S9: =IFERROR(VLOOKUP(C9,MOSFET!$A$4:$Z$19,10,FALSE),"") -> 800 | T9: =IFERROR(VLOOKUP(B9,MOSFET!$A$4:$Z$19,13,FALSE),"") -> 29 | U9: =IFERROR(VLOOKUP(C9,MOSFET!$A$4:$Z$19,13,FALSE),"") -> 43 | V9: =IFERROR(VLOOKUP(B9,MOSFET!$A$4:$Z$19,14,FALSE),"") -> 15 | W9: =IFERROR(VLOOKUP(C9,MOSFET!$A$4:$Z$19,14,FALSE),"") -> 23 | X9: =IFERROR(VLOOKUP(B9,MOSFET!$A$4:$Z$19,12,FALSE),"") -> 40 | Y9: =IFERROR(VLOOKUP(C9,MOSFET!$A$4:$Z$19,12,FALSE),"") -> 76 | Z9: =IFERROR(VLOOKUP(B9,MOSFET!$A$4:$Z$19,11,FALSE),"") -> 200 | AA9: =IFERROR(VLOOKUP(C9,MOSFET!$A$4:$Z$19,11,FALSE),"") -> 240 | AB9: =IFERROR(Config!$B$33*MIN(1,Config!$B$26/R9)+Config!$B$34*MIN(1,Config!$B$27/T9)+Config!$B$35*MIN(1,Config!$B$28/V9)+Config!$B$36*MIN(1,Config!$B$29/X9)+Config!$B$37*MIN(1,Config!$B$30/Z9)+Config!$B$38*MIN(1,K9/Config!$B$22)+Config!$B$39*IF(M9="YES",1,0.9),"") -> 0.8228592 | AC9: =IFERROR(Config!$B$33*MIN(1,Config!$C$26/S9)+Config!$B$34*MIN(1,Config!$C$27/U9)+Config!$B$35*MIN(1,Config!$C$28/W9)+Config!$B$36*MIN(1,Config!$C$29/Y9)+Config!$B$37*MIN(1,Config!$C$30/AA9)+Config!$B$38*MIN(1,L9/Config!$B$22)+Config!$B$39*IF(N9="YES",1,0.9),"") -> 0.62299715 | AD9: 100 | AE9: 100 | AF9: =IFERROR(1/(2*PI()*AD9*R9*0.000000000001)/1000000,"") -> 2.273642 | AG9: =IFERROR(1/(2*PI()*AE9*S9*0.000000000001)/1000000,"") -> 1.9894368 | AH9: =IFERROR(ABS(AF9-AG9)/MIN(AF9,AG9),"") -> 0.14285714 | AI9: =IFERROR(Config!$B$43*MIN(R9,S9)/MAX(R9,S9)+Config!$B$44*MIN(T9,U9)/MAX(T9,U9)+Config!$B$45*MIN(V9,W9)/MAX(V9,W9),"") -> 0.81148888 | AJ9: =IF(OR(O9="FAIL",P9="FAIL",Q9="FAIL"),0,Config!$B$49*MIN(AB9,AC9)+Config!$B$50*AI9) -> 0.6606955 | AK9: =IF(AJ9>=Config!$B$55,"*****",IF(AJ9>=Config!$B$56,"****",IF(AJ9>=Config!$B$57,"***",IF(AJ9>=Config!$B$58,"**","*")))) -> ** | AL9: =IF(OR(O9="FAIL",P9="FAIL",Q9="FAIL"),"*",IF(AND(E9="TESTED",F9="PASS",D9<>"ARCHIVE"),AK9,IF(LEN(AK9)>Config!$B$59,REPT("*",Config!$B$59),AK9))) -> ** | AM9: =IF(OR(O9="FAIL",P9="FAIL",Q9="FAIL"),"NOT VALIDATED",IF(E9="NOT TESTED","WAITING VALIDATION",IF(F9="PASS","VALIDATED",IF(F9="FAIL","NOT VALIDATED","WAITING VALIDATION")))) -> WAITING VALIDATION
A10: P1 | B10: FQP3P20 | C10: FQP3N30 | D10: =IF(OR(VLOOKUP(B10,MOSFET!$A$4:$Z$19,20,FALSE)="ARCHIVE",VLOOKUP(C10,MOSFET!$A$4:$Z$19,20,FALSE)="ARCHIVE"),"ARCHIVE",IF(OR(VLOOKUP(B10,MOSFET!$A$4:$Z$19,20,FALSE)="DATABASE",VLOOKUP(C10,MOSFET!$A$4:$Z$19,20,FALSE)="DATABASE"),"DATABASE","CURRENT")) -> ARCHIVE | E10: =IFERROR(VLOOKUP(A10,Selection!$B$26:$F$31,2,FALSE),"NOT TESTED") -> TESTED | F10: =IFERROR(VLOOKUP(A10,Selection!$B$26:$F$31,3,FALSE),"NOT TESTED") -> FAIL | G10: =IFERROR(VLOOKUP(B10,MOSFET!$A$4:$Z$19,5,FALSE),"") -> 200 | H10: =IFERROR(VLOOKUP(C10,MOSFET!$A$4:$Z$19,5,FALSE),"") -> 300 | I10: =IFERROR(VLOOKUP(B10,MOSFET!$A$4:$Z$19,6,FALSE),"") -> 2.8 | J10: =IFERROR(VLOOKUP(C10,MOSFET!$A$4:$Z$19,6,FALSE),"") -> 3.2 | K10: =IFERROR(VLOOKUP(B10,MOSFET!$A$4:$Z$19,24,FALSE),"") -> 73.33856 | L10: =IFERROR(VLOOKUP(C10,MOSFET!$A$4:$Z$19,24,FALSE),"") -> 73.699388 | M10: =IFERROR(VLOOKUP(B10,MOSFET!$A$4:$Z$19,16,FALSE),"") -> NO | N10: =IFERROR(VLOOKUP(C10,MOSFET!$A$4:$Z$19,16,FALSE),"") -> NO | O10: =IF(MIN(G10,H10)>=Config!$B$19,"OK","FAIL") -> OK | P10: =IF(MIN(I10,J10)>=Config!$B$14*Config!$B$20,"OK","FAIL") -> OK | Q10: =IF(MIN(K10,L10)>=Config!$B$21,"OK","FAIL") -> OK | R10: =IFERROR(VLOOKUP(B10,MOSFET!$A$4:$Z$19,10,FALSE),"") -> 190 | S10: =IFERROR(VLOOKUP(C10,MOSFET!$A$4:$Z$19,10,FALSE),"") -> 175 | T10: =IFERROR(VLOOKUP(B10,MOSFET!$A$4:$Z$19,13,FALSE),"") -> 6 | U10: =IFERROR(VLOOKUP(C10,MOSFET!$A$4:$Z$19,13,FALSE),"") -> 5.5 | V10: =IFERROR(VLOOKUP(B10,MOSFET!$A$4:$Z$19,14,FALSE),"") -> 2.9 | W10: =IFERROR(VLOOKUP(C10,MOSFET!$A$4:$Z$19,14,FALSE),"") -> 2.5 | X10: =IFERROR(VLOOKUP(B10,MOSFET!$A$4:$Z$19,12,FALSE),"") -> 7.5 | Y10: =IFERROR(VLOOKUP(C10,MOSFET!$A$4:$Z$19,12,FALSE),"") -> 6 | Z10: =IFERROR(VLOOKUP(B10,MOSFET!$A$4:$Z$19,11,FALSE),"") -> 45 | AA10: =IFERROR(VLOOKUP(C10,MOSFET!$A$4:$Z$19,11,FALSE),"") -> 40 | AB10: =IFERROR(Config!$B$33*MIN(1,Config!$B$26/R10)+Config!$B$34*MIN(1,Config!$B$27/T10)+Config!$B$35*MIN(1,Config!$B$28/V10)+Config!$B$36*MIN(1,Config!$B$29/X10)+Config!$B$37*MIN(1,Config!$B$30/Z10)+Config!$B$38*MIN(1,K10/Config!$B$22)+Config!$B$39*IF(M10="YES",1,0.9),"") -> 0.99 | AC10: =IFERROR(Config!$B$33*MIN(1,Config!$C$26/S10)+Config!$B$34*MIN(1,Config!$C$27/U10)+Config!$B$35*MIN(1,Config!$C$28/W10)+Config!$B$36*MIN(1,Config!$C$29/Y10)+Config!$B$37*MIN(1,Config!$C$30/AA10)+Config!$B$38*MIN(1,L10/Config!$B$22)+Config!$B$39*IF(N10="YES",1,0.9),"") -> 0.98583333 | AD10: 100 | AE10: 100 | AF10: =IFERROR(1/(2*PI()*AD10*R10*0.000000000001)/1000000,"") -> 8.376576 | AG10: =IFERROR(1/(2*PI()*AE10*S10*0.000000000001)/1000000,"") -> 9.0945682 | AH10: =IFERROR(ABS(AF10-AG10)/MIN(AF10,AG10),"") -> 0.085714286 | AI10: =IFERROR(Config!$B$43*MIN(R10,S10)/MAX(R10,S10)+Config!$B$44*MIN(T10,U10)/MAX(T10,U10)+Config!$B$45*MIN(V10,W10)/MAX(V10,W10),"") -> 0.91154719 | AJ10: =IF(OR(O10="FAIL",P10="FAIL",Q10="FAIL"),0,Config!$B$49*MIN(AB10,AC10)+Config!$B$50*AI10) -> 0.9709761 | AK10: =IF(AJ10>=Config!$B$55,"*****",IF(AJ10>=Config!$B$56,"****",IF(AJ10>=Config!$B$57,"***",IF(AJ10>=Config!$B$58,"**","*")))) -> ***** | AL10: =IF(OR(O10="FAIL",P10="FAIL",Q10="FAIL"),"*",IF(AND(E10="TESTED",F10="PASS",D10<>"ARCHIVE"),AK10,IF(LEN(AK10)>Config!$B$59,REPT("*",Config!$B$59),AK10))) -> **** | AM10: =IF(OR(O10="FAIL",P10="FAIL",Q10="FAIL"),"NOT VALIDATED",IF(E10="NOT TESTED","WAITING VALIDATION",IF(F10="PASS","VALIDATED",IF(F10="FAIL","NOT VALIDATED","WAITING VALIDATION")))) -> NOT VALIDATED

Sheet MOSFET
A1: Q17 Q5/Q6 — MOSFET Compatibility Database
A2: Manufacturer-datasheet data copied from the source workbook. R7/R8 are fixed at 100 Ω. gfs and VGS(th) are intentionally omitted from the score.
A3: Model | B3: Role | C3: Channel | D3: Manufacturer | E3: Vdss (V) | F3: Id max (A) | G3: Pd @Tc25 (W) | H3: RθJC max (°C/W) | I3: Tj max (°C) | J3: Ciss typ (pF) | K3: Coss typ (pF) | L3: Crss typ (pF) | M3: Qg typ (nC) | N3: Qgd typ (nC) | O3: Package | P3: Insulated | Q3: Manufacturer datasheet | R3: Distributor note | S3: Mouser URL | T3: Availability | U3: Data note | V3: Preselect | W3: Tj est (°C) | X3: Thermal margin (°C) | Y3: Vdss headroom | Z3: Id headroom
A4: FQPF7P20 | B4: Q5 | C4: P | D4: onsemi | E4: 200 | F4: 5.2 | G4: 45 | H4: 2.78 | I4: 150 | J4: 590 | K4: 140 | L4: 25 | M4: 19 | N4: 9.5 | O4: TO-220F | P4: YES | Q4: https://www.onsemi.com/download/data-sheet/pdf/fqpf7p20-d.pdf | R4: Current Q17 Q5 baseline | T4: CURRENT | U4: onsemi manufacturer datasheet | V4: =IF(AND(E4>=Config!$B$19,F4>=Config!$B$14*Config!$B$20,X4>=Config!$B$21),"YES","NO") -> YES | W4: =Config!$B$16+(Config!$B$14*Config!$B$15)*H4 -> 77.716168 | X4: =I4-W4 -> 72.283832 | Y4: =E4/Config!$B$19 -> 1.3333333 | Z4: =F4/(Config!$B$14*Config!$B$20) -> 13.488975
A5: FQP3P20 | B5: Q5 | C5: P | D5: onsemi | E5: 200 | F5: 2.8 | G5: 52 | H5: 2.4 | I5: 150 | J5: 190 | K5: 45 | L5: 7.5 | M5: 6 | N5: 2.9 | O5: TO-220 | P5: NO | Q5: https://www.onsemi.com/pdf/datasheet/fqp3p20-d.pdf | R5: ARCHIVE — historical Q17 reference; no longer available | T5: ARCHIVE | U5: Historical Q17 reference; no longer sourced for new builds | V5: =IF(AND(E5>=Config!$B$19,F5>=Config!$B$14*Config!$B$20,X5>=Config!$B$21),"YES","NO") -> YES | W5: =Config!$B$16+(Config!$B$14*Config!$B$15)*H5 -> 76.66144 | X5: =I5-W5 -> 73.33856 | Y5: =E5/Config!$B$19 -> 1.3333333 | Z5: =F5/(Config!$B$14*Config!$B$20) -> 7.2632944
A6: FQP3N30 | B6: Q6 | C6: N | D6: onsemi | E6: 300 | F6: 3.2 | G6: 55 | H6: 2.27 | I6: 150 | J6: 175 | K6: 40 | L6: 6 | M6: 5.5 | N6: 2.5 | O6: TO-220 | P6: NO | Q6: https://www.onsemi.com/pdf/datasheet/fqp3n30-d.pdf | R6: ARCHIVE — historical companion to FQP3P20 | T6: ARCHIVE | U6: Historical companion to FQP3P20 | V6: =IF(AND(E6>=Config!$B$19,F6>=Config!$B$14*Config!$B$20,X6>=Config!$B$21),"YES","NO") -> YES | W6: =Config!$B$16+(Config!$B$14*Config!$B$15)*H6 -> 76.300612 | X6: =I6-W6 -> 73.699388 | Y6: =E6/Config!$B$19 -> 2 | Z6: =F6/(Config!$B$14*Config!$B$20) -> 8.3009079
A7: FQP3N80C | B7: Q6 | C7: N | D7: onsemi | E7: 800 | F7: 3 | G7: 107 | H7: 1.17 | I7: 150 | J7: 543 | K7: 54 | L7: 5.5 | M7: 13 | N7: 5.8 | O7: TO-220 | P7: NO | Q7: https://www.onsemi.com/download/data-sheet/pdf/fqpf3n80c-d.pdf | R7: Same manufacturer datasheet covers FQP3N80C and FQPF3N80C | T7: CURRENT | U7: onsemi; non-insulated version of 3N80C | V7: =IF(AND(E7>=Config!$B$19,F7>=Config!$B$14*Config!$B$20,X7>=Config!$B$21),"YES","NO") -> YES | W7: =Config!$B$16+(Config!$B$14*Config!$B$15)*H7 -> 73.247452 | X7: =I7-W7 -> 76.752548 | Y7: =E7/Config!$B$19 -> 5.3333333 | Z7: =F7/(Config!$B$14*Config!$B$20) -> 7.7821012
A8: FQPF3N80C | B8: Q6 | C8: N | D8: onsemi | E8: 800 | F8: 3 | G8: 39 | H8: 3.2 | I8: 150 | J8: 543 | K8: 54 | L8: 5.5 | M8: 13 | N8: 5.8 | O8: TO-220F | P8: YES | Q8: https://www.onsemi.com/download/data-sheet/pdf/fqpf3n80c-d.pdf | R8: Current Q17 Q6 baseline | T8: CURRENT | U8: Current Q17 Q6 baseline | V8: =IF(AND(E8>=Config!$B$19,F8>=Config!$B$14*Config!$B$20,X8>=Config!$B$21),"YES","NO") -> YES | W8: =Config!$B$16+(Config!$B$14*Config!$B$15)*H8 -> 78.88192 | X8: =I8-W8 -> 71.11808 | Y8: =E8/Config!$B$19 -> 5.3333333 | Z8: =F8/(Config!$B$14*Config!$B$20) -> 7.7821012
A9: FQPF2N80 | B9: Q6 | C9: N | D9: onsemi | E9: 800 | F9: 1.5 | G9: 35 | H9: 3.57 | I9: 150 | J9: 425 | K9: 45 | L9: 5.5 | M9: 12 | N9: 6 | O9: TO-220F | P9: YES | Q9: https://www.onsemi.com/download/data-sheet/pdf/fqpf2n80-d.pdf | R9: Existing Q17 candidate | T9: DATABASE | U9: Not retained in current >=3-star pair list | V9: =IF(AND(E9>=Config!$B$19,F9>=Config!$B$14*Config!$B$20,X9>=Config!$B$21),"YES","NO") -> YES | W9: =Config!$B$16+(Config!$B$14*Config!$B$15)*H9 -> 79.908892 | X9: =I9-W9 -> 70.091108 | Y9: =E9/Config!$B$19 -> 5.3333333 | Z9: =F9/(Config!$B$14*Config!$B$20) -> 3.8910506
A10: FQPF4N90C | B10: Q6 | C10: N | D10: onsemi | E10: 900 | F10: 4 | G10: 47 | H10: 2.66 | I10: 150 | J10: 740 | K10: 65 | L10: 5.6 | M10: 17 | N10: 7.5 | O10: TO-220F | P10: YES | Q10: https://www.onsemi.com/download/data-sheet/pdf/fqpf4n90c-d.pdf | R10: Existing Q17 candidate | T10: CURRENT | U10: Current Q6 candidate | V10: =IF(AND(E10>=Config!$B$19,F10>=Config!$B$14*Config!$B$20,X10>=Config!$B$21),"YES","NO") -> YES | W10: =Config!$B$16+(Config!$B$14*Config!$B$15)*H10 -> 77.383096 | X10: =I10-W10 -> 72.616904 | Y10: =E10/Config!$B$19 -> 6 | Z10: =F10/(Config!$B$14*Config!$B$20) -> 10.376135
A11: IXFP30N25X3 | B11: Q6 | C11: N | D11: Littelfuse / IXYS | E11: 250 | F11: 30 | G11: 170 | H11: 0.73 | I11: 150 | J11: 1450 | K11: 266 | L11: 1 | M11: 21 | N11: 6 | O11: TO-220 | P11: NO | Q11: https://www.littelfuse.com/assetdocs/littelfuse-discrete-mosfets-ixf-30n25x3-datasheet?assetguid=f98c5907-f43b-4415-a418-45a0a7855e6d | R11: Added from Mouser search 07/10/2026 | S11: https://www.mouser.fr/fr/ProductDetail/IXYS/IXFP30N25X3 | T11: DATABASE | U11: High Ciss; retained for database comparison | V11: =IF(AND(E11>=Config!$B$19,F11>=Config!$B$14*Config!$B$20,X11>=Config!$B$21),"YES","NO") -> YES | W11: =Config!$B$16+(Config!$B$14*Config!$B$15)*H11 -> 72.026188 | X11: =I11-W11 -> 77.973812 | Y11: =E11/Config!$B$19 -> 1.6666667 | Z11: =F11/(Config!$B$14*Config!$B$20) -> 77.821012
A12: IXFP44N25X3 | B12: Q6 | C12: N | D12: Littelfuse / IXYS | E12: 250 | F12: 44 | G12: 240 | H12: 0.52 | I12: 150 | J12: 2200 | K12: 405 | L12: 1 | M12: 33 | N12: 10 | O12: TO-220 | P12: NO | Q12: https://www.littelfuse.com/assetdocs/littelfuse-discrete-mosfets-ixf-44n25x3-datasheet?assetguid=d4d53a59-e025-4cd0-9ea6-9898c3e6cbeb | R12: Added from Mouser search 07/10/2026 | S12: https://www.mouser.fr/fr/ProductDetail/IXYS/IXFP44N25X3 | T12: DATABASE | U12: High Ciss; retained for database comparison | V12: =IF(AND(E12>=Config!$B$19,F12>=Config!$B$14*Config!$B$20,X12>=Config!$B$21),"YES","NO") -> YES | W12: =Config!$B$16+(Config!$B$14*Config!$B$15)*H12 -> 71.443312 | X12: =I12-W12 -> 78.556688 | Y12: =E12/Config!$B$19 -> 1.6666667 | Z12: =F12/(Config!$B$14*Config!$B$20) -> 114.13748
A13: IXFP38N30X3 | B13: Q6 | C13: N | D13: Littelfuse / IXYS | E13: 300 | F13: 38 | G13: 240 | H13: 0.52 | I13: 150 | J13: 2240 | K13: 330 | L13: 1.3 | M13: 35 | N13: 11 | O13: TO-220 | P13: NO | Q13: https://www.littelfuse.com/assetdocs/littelfuse-discrete-mosfets-ixf-38n30x3-datasheet?assetguid=bf5a0d57-37da-484a-a94b-aa873a26c7d4 | R13: Added from Mouser search 07/10/2026 | S13: https://www.mouser.fr/fr/ProductDetail/IXYS/IXFP38N30X3 | T13: DATABASE | U13: High Ciss; retained for database comparison | V13: =IF(AND(E13>=Config!$B$19,F13>=Config!$B$14*Config!$B$20,X13>=Config!$B$21),"YES","NO") -> YES | W13: =Config!$B$16+(Config!$B$14*Config!$B$15)*H13 -> 71.443312 | X13: =I13-W13 -> 78.556688 | Y13: =E13/Config!$B$19 -> 2 | Z13: =F13/(Config!$B$14*Config!$B$20) -> 98.573281
A14: IRFI9620GPBF | B14: Q5 | C14: P | D14: Vishay | E14: 200 | F14: 3 | G14: 30 | H14: 4.1 | I14: 175 | J14: 340 | K14: 110 | L14: 33 | M14: 15 | N14: 8.4 | O14: TO-220 FULLPAK | P14: YES | Q14: https://www.vishay.com/docs/91166/irfi9620g.pdf | R14: New Q5 candidate; FULLPAK isolated | S14: https://eu.mouser.com/ProductDetail/Vishay-Semiconductors/IRFI9620GPBF | T14: CURRENT | U14: Vishay manufacturer datasheet | V14: =IF(AND(E14>=Config!$B$19,F14>=Config!$B$14*Config!$B$20,X14>=Config!$B$21),"YES","NO") -> YES | W14: =Config!$B$16+(Config!$B$14*Config!$B$15)*H14 -> 81.37996 | X14: =I14-W14 -> 93.62004 | Y14: =E14/Config!$B$19 -> 1.3333333 | Z14: =F14/(Config!$B$14*Config!$B$20) -> 7.7821012
A15: IRFI620GPBF | B15: Q6 | C15: N | D15: Vishay | E15: 200 | F15: 4.1 | G15: 30 | H15: 4.1 | I15: 150 | J15: 260 | K15: 100 | L15: 30 | M15: 14 | N15: 7.9 | O15: TO-220 FULLPAK | P15: YES | Q15: https://www.vishay.com/docs/91146/91146.pdf | R15: New Q6 candidate; FULLPAK isolated | S15: https://eu.mouser.com/ProductDetail/Vishay-Semiconductors/IRFI620GPBF | T15: CURRENT | U15: Vishay manufacturer datasheet | V15: =IF(AND(E15>=Config!$B$19,F15>=Config!$B$14*Config!$B$20,X15>=Config!$B$21),"YES","NO") -> YES | W15: =Config!$B$16+(Config!$B$14*Config!$B$15)*H15 -> 81.37996 | X15: =I15-W15 -> 68.62004 | Y15: =E15/Config!$B$19 -> 1.3333333 | Z15: =F15/(Config!$B$14*Config!$B$20) -> 10.635538
A16: IRFI9630GPBF | B16: Q5 | C16: P | D16: Vishay | E16: 200 | F16: 4.3 | G16: 35 | H16: 3.6 | I16: 150 | J16: 700 | K16: 200 | L16: 40 | M16: 29 | N16: 15 | O16: TO-220 FULLPAK | P16: YES | Q16: https://www.vishay.com/docs/91167/irfi9630g.pdf | R16: Additional isolated Q5 candidate | S16: https://eu.mouser.com/ProductDetail/Vishay-Semiconductors/IRFI9630GPBF | T16: CURRENT | U16: Vishay manufacturer datasheet | V16: =IF(AND(E16>=Config!$B$19,F16>=Config!$B$14*Config!$B$20,X16>=Config!$B$21),"YES","NO") -> YES | W16: =Config!$B$16+(Config!$B$14*Config!$B$15)*H16 -> 79.99216 | X16: =I16-W16 -> 70.00784 | Y16: =E16/Config!$B$19 -> 1.3333333 | Z16: =F16/(Config!$B$14*Config!$B$20) -> 11.154345
A17: IRFI630GPBF | B17: Q6 | C17: N | D17: Vishay | E17: 200 | F17: 5.9 | G17: 35 | H17: 3.6 | I17: 150 | J17: 800 | K17: 240 | L17: 76 | M17: 43 | N17: 23 | O17: TO-220 FULLPAK | P17: YES | Q17: https://www.vishay.com/docs/91148/91148.pdf | R17: Additional isolated Q6 candidate | S17: https://eu.mouser.com/ProductDetail/Vishay-Semiconductors/IRFI630GPBF | T17: CURRENT | U17: Vishay manufacturer datasheet | V17: =IF(AND(E17>=Config!$B$19,F17>=Config!$B$14*Config!$B$20,X17>=Config!$B$21),"YES","NO") -> YES | W17: =Config!$B$16+(Config!$B$14*Config!$B$15)*H17 -> 79.99216 | X17: =I17-W17 -> 70.00784 | Y17: =E17/Config!$B$19 -> 1.3333333 | Z17: =F17/(Config!$B$14*Config!$B$20) -> 15.304799
A18: IRFI9640GPBF | B18: Q5 | C18: P | D18: Vishay | E18: 200 | F18: 6.1 | G18: 40 | H18: 3.1 | I18: 150 | J18: 1200 | K18: 370 | L18: 80 | M18: 44 | N18: 27 | O18: TO-220 FULLPAK | P18: YES | Q18: https://www.vishay.com/docs/91169/irfi9640g.pdf | R18: Additional isolated Q5 candidate; heavier gate load | S18: https://eu.mouser.com/ProductDetail/Vishay-Semiconductors/IRFI9640GPBF | T18: DATABASE | U18: Vishay manufacturer datasheet | V18: =IF(AND(E18>=Config!$B$19,F18>=Config!$B$14*Config!$B$20,X18>=Config!$B$21),"YES","NO") -> YES | W18: =Config!$B$16+(Config!$B$14*Config!$B$15)*H18 -> 78.60436 | X18: =I18-W18 -> 71.39564 | Y18: =E18/Config!$B$19 -> 1.3333333 | Z18: =F18/(Config!$B$14*Config!$B$20) -> 15.823606
A19: IRFI640GPBF | B19: Q6 | C19: N | D19: Vishay | E19: 200 | F19: 9.8 | G19: 40 | H19: 3.1 | I19: 150 | J19: 1300 | K19: 400 | L19: 130 | M19: 70 | N19: 39 | O19: TO-220 FULLPAK | P19: YES | Q19: https://www.vishay.com/docs/91150/91150.pdf | R19: Additional isolated Q6 candidate; heavier gate load | S19: https://eu.mouser.com/ProductDetail/Vishay-Semiconductors/IRFI640GPBF | T19: DATABASE | U19: Vishay manufacturer datasheet | V19: =IF(AND(E19>=Config!$B$19,F19>=Config!$B$14*Config!$B$20,X19>=Config!$B$21),"YES","NO") -> YES | W19: =Config!$B$16+(Config!$B$14*Config!$B$15)*H19 -> 78.60436 | X19: =I19-W19 -> 71.39564 | Y19: =E19/Config!$B$19 -> 1.3333333 | Z19: =F19/(Config!$B$14*Config!$B$20) -> 25.42153

Sheet Validation
A1: Q17 Q5/Q6 — Evidence / Physical Validation at R7 = R8 = 100 Ω
A2: Evidence: NONE = calculation only; LEGACY = previous Q17 evidence; CURRENT = repeated on the current board. Bench result always refers to the fixed 100 Ω / 100 Ω implementation.
A3: Pair | B3: Q5 | C3: Q6 | D3: Evidence | E3: Bench result | F3: Test notes / origin | G3: Status
A4: P8 | B4: FQPF7P20 | C4: FQPF3N80C | D4: LEGACY | E4: PASS | F4: Legacy Q17 evidence at 100 Ω / 100 Ω; repeat on current 3.1 board. | G4: =IF(D4="CURRENT",IF(E4="PASS","CURRENT VALIDATED",IF(E4="FAIL","CURRENT FAILED","CURRENT INCOMPLETE")),IF(D4="LEGACY",IF(E4="PASS","LEGACY EVIDENCE",IF(E4="FAIL","LEGACY FAILED","LEGACY INCOMPLETE")),"NOT VALIDATED")) -> LEGACY EVIDENCE
A5: P7 | B5: FQPF7P20 | C5: FQP3N80C | D5: NONE | E5: NOT TESTED | F5: Non-insulated Q6 variant. | G5: =IF(D5="CURRENT",IF(E5="PASS","CURRENT VALIDATED",IF(E5="FAIL","CURRENT FAILED","CURRENT INCOMPLETE")),IF(D5="LEGACY",IF(E5="PASS","LEGACY EVIDENCE",IF(E5="FAIL","LEGACY FAILED","LEGACY INCOMPLETE")),"NOT VALIDATED")) -> NOT VALIDATED
A6: P21 | B6: IRFI9620GPBF | C6: IRFI620GPBF | D6: NONE | E6: NOT TESTED | F6: Low absolute gate burden; larger fixed-100 Ω pole mismatch. | G6: =IF(D6="CURRENT",IF(E6="PASS","CURRENT VALIDATED",IF(E6="FAIL","CURRENT FAILED","CURRENT INCOMPLETE")),IF(D6="LEGACY",IF(E6="PASS","LEGACY EVIDENCE",IF(E6="FAIL","LEGACY FAILED","LEGACY INCOMPLETE")),"NOT VALIDATED")) -> NOT VALIDATED
A7: P10 | B7: FQPF7P20 | C7: FQPF4N90C | D7: NONE | E7: NOT TESTED | F7: Current candidate. | G7: =IF(D7="CURRENT",IF(E7="PASS","CURRENT VALIDATED",IF(E7="FAIL","CURRENT FAILED","CURRENT INCOMPLETE")),IF(D7="LEGACY",IF(E7="PASS","LEGACY EVIDENCE",IF(E7="FAIL","LEGACY FAILED","LEGACY INCOMPLETE")),"NOT VALIDATED")) -> NOT VALIDATED
A8: P22 | B8: IRFI9630GPBF | C8: IRFI630GPBF | D8: NONE | E8: NOT TESTED | F8: Higher absolute gate burden. | G8: =IF(D8="CURRENT",IF(E8="PASS","CURRENT VALIDATED",IF(E8="FAIL","CURRENT FAILED","CURRENT INCOMPLETE")),IF(D8="LEGACY",IF(E8="PASS","LEGACY EVIDENCE",IF(E8="FAIL","LEGACY FAILED","LEGACY INCOMPLETE")),"NOT VALIDATED")) -> NOT VALIDATED
A9: P1 | B9: FQP3P20 | C9: FQP3N30 | D9: LEGACY | E9: PASS | F9: Historical/original pair; archive only for new builds. | G9: =IF(D9="CURRENT",IF(E9="PASS","CURRENT VALIDATED",IF(E9="FAIL","CURRENT FAILED","CURRENT INCOMPLETE")),IF(D9="LEGACY",IF(E9="PASS","LEGACY EVIDENCE",IF(E9="FAIL","LEGACY FAILED","LEGACY INCOMPLETE")),"NOT VALIDATED")) -> LEGACY EVIDENCE

Sheet Notes
A1: Q5/Q6 MOSFET Compatibility — Method, Assumptions and Validation | J1: Selection label | K1: Pair ID
J2: FQPF7P20 / FQPF3N80C | K2: P8
A3: Step | B3: Principle | C3: Why it is used | D3: Limit / validation | J3: FQPF7P20 / FQP3N80C | K3: P7
A4: 1 | B4: Q5/Q6 are the Q17 Class-A driver/error devices; Iq ≈ 77.1 mA. | C4: Defines the real device role. They are not treated as a conventional matched complementary output pair. | D4: Use current-board measurements when available. | J4: IRFI9620GPBF / IRFI620GPBF | K4: P21
A5: 2 | B5: R7 = 100 Ω and R8 = 100 Ω are fixed implementation values. | C5: Removes gate-resistor optimization from this workbook. | D5: The workbook only calculates the resulting fixed-100 Ω dynamic mismatch. | J5: FQPF7P20 / FQPF4N90C | K5: P10
A6: 3 | B6: Hard screens: |Vdss| ≥ 150 V; Idmax ≥ 5×Iq; thermal margin ≥ 30°C. | C6: Prevents a score from hiding an unsuitable device. | D6: Not a complete SOA/heatsink proof. | J6: IRFI9630GPBF / IRFI630GPBF | K6: P22
A7: 4 | B7: Each device is scored against the current role-specific Q17 baseline. | C7: Optimizes Q5 and Q6 for their own roles rather than forcing N/P symmetry. | D7: Baseline scoring is an engineering screening heuristic. | J7: FQP3P20 / FQP3N30 | K7: P1
A8: 5 | B8: Individual score: Ciss 35%, Qg 15%, Qgd 10%, Crss 5%, Coss 5%, thermal 20%, implementation 10%. | C8: Emphasizes absolute driver burden and thermal/practical margin. | D8: Capacitances and charge vary with operating conditions.
A9: 6 | B9: Fixed-100 Ω pair balance: Ciss/pole symmetry 70%, Qg similarity 15%, Qgd similarity 15%. | C9: Equal R7/R8 makes Ciss mismatch directly relevant to relative gate poles. | D9: Still first-order; validate on the amplifier.
A10: 7 | B10: Overall compatibility = 80% × MIN(Q5 score,Q6 score) + 20% × pair balance. | C10: A weak device cannot be hidden by a strong partner. | D10: The 80/20 split is explicit and editable in Config.
A11: 8 | B11: VGS(th), datasheet gfs and guessed |VGS|@77mA are not scored. | C11: Available low-current transfer data are not uniformly precise enough and the device roles are asymmetric. | D11: Use equally reliable measured/SPICE data if available later.
A12: 9 | B12: Fit stars describe calculated compatibility; uncapped final Q17 status requires TESTED/PASS bench evidence on a non-archive pair. | C12: Separates theoretical screening from physical evidence. | D12: Historical/ARCHIVE pairs remain capped even when their old bench test passed.
A14: SOURCES
A15: Source | B15: Type | C15: URL / reference | D15: Use
A16: Q17-Mini 3.1 technical documentation | B16: Project file | C16: Q17_Mini_3.1_Technical_Documentation_Draft_Rev_1.1.docx | D16: Q5/Q6 role and ~77.1 mA operating point.
A17: onsemi | B17: Manufacturer datasheets | C17: See MOSFET sheet URLs | D17: Current/historical onsemi devices.
A18: Vishay | B18: Manufacturer datasheets | C18: See MOSFET sheet URLs | D18: IRFI candidate devices.
A19: Littelfuse / IXYS | B19: Manufacturer datasheets | C19: See MOSFET sheet URLs | D19: Database-only IXFP candidates.
A20: Legacy Q17 pair table | B20: Project file | C20: Q17-Power-Transistors-Selection-Rgate.xlsx | D20: Historical P8 / P1 evidence at 100 Ω / 100 Ω.
A22: 1.0b1 — NEW WORKBOOK OBJECTIVE
A23: Workbook | B23: Renamed to Q5_Q6_MOSFET_Compatibility_1.0b1. | C23: Primary objective is MOSFET compatibility/selection, not resistor calculation. | D23: Derived from source b11.
A24: R7/R8 | B24: All E24/ideal/recommended resistor calculations removed. | C24: R7 and R8 are fixed at 100 Ω. | D24: Only the resulting fixed-100 Ω mismatch is displayed.
A25: Scoring | B25: Role-specific Q5/Q6 suitability + smaller pair-balance term. | C25: Better reflects the asymmetric Q5/Q6 Q17 roles. | D25: All weights are exposed in Config.
A26: Evidence | B26: Validation no longer asks for resistor values. | C26: Physical test input = NOT TESTED/TESTED + NOT TESTED/PASS/FAIL at fixed 100 Ω / 100 Ω. | D26: TESTED/PASS on a non-archive pair is required to uncap five-star final status.
A28: 1.0b2 | B28: Added in-cell data bars to Summary Q5 score and Q6 score. | C28: Purple bar for Q5 and cyan bar for Q6, following the Q15/Q16 compatibility workbook presentation. | D28: Display-only change; compatibility calculations and ranking are unchanged.
A29: 1.0b3 | B29: Fixed Summary Q5/Q6 score data-bar scale. | C29: Data bars now use an absolute 0% to 100% scale instead of automatic min/max scaling. | D29: Display-only change; scores and ranking unchanged.
A30: 1.0b4 | B30: Added an in-cell data bar to Summary 100 Ω mismatch. | C30: Fixed 0% to 100% scale so bar length shows the true mismatch magnitude. | D30: Display-only change; compatibility calculations and ranking are unchanged.
A31: 1.0b5 | B31: Added an in-cell data bar to Summary Compatibility. | C31: Fixed 0% to 100% scale, consistent with Q5 score, Q6 score and 100 Ω mismatch. | D31: Display-only change; compatibility calculations and ranking are unchanged.
A32: 1.0b6 | B32: Renamed Summary 100 Ω mismatch header. | C32: Header now reads '100 Ω pole' / 'mismatch' on two centered lines. | D32: Display-only change; data bar and calculations are unchanged.
A33: 1.0b7 | B33: Pair balance display and Summary data-bar cleanup. | C33: Pair balance is now displayed as a percentage. The four Summary data bars were rebuilt with one fixed 0%–100% rule each. | D33: No score formula or ranking changed.
A34: 1.0b8 | B34: Simplified Summary and Selection physical-test input. | C34: Removed Q17 stars from Summary. In Selection, removed unused Use and redundant Fixed R7/R8 columns; renamed Evidence to Test evidence and added a note explaining Bench result behavior. | D34: Bench-result logic is unchanged: Selection overrides Validation only when Test evidence is LEGACY or CURRENT.
A35: 1.0b9 | B35: Simplified physical-test terminology. | C35: Test evidence is now NOT TESTED / TESTED. Status is now WAITING VALIDATION / VALIDATED / NOT VALIDATED and is calculated automatically from Test evidence + Bench result. | D35: Selection is the authoritative physical-test input. P8 and historical P1 are marked TESTED/PASS; untested candidates remain NOT TESTED.

Sheet Summary
A1: Q5/Q6 MOSFET Compatibility — Q17 Summary
A2: Fixed R7/R8 | C2: 100 Ω / 100 Ω | E2: Pairs in table | G2: 6 | H2: Version | I2: 1.0b9 | J2: Date | K2: 46304
A3: Current-build candidates are ranked by compatibility score. Archive devices remain visible in the same table but are kept last. Overall compatibility = 80% × weaker individual device score + 20% × fixed-100 Ω pair balance.
A5: No. | B5: Pair | C5: Q5 (P) | D5: Q6 (N) | E5: Q5 score | F5: Q6 score | G5: 100 Ω pole mismatch | H5: Pair balance | I5: Compatibility | J5: Test evidence | K5: Status
A6: 1 | B6: P8 | C6: =VLOOKUP(B6,Calculations!$A$5:$AM$10,2,FALSE) -> FQPF7P20 | D6: =VLOOKUP(B6,Calculations!$A$5:$AM$10,3,FALSE) -> FQPF3N80C | E6: =VLOOKUP(B6,Calculations!$A$5:$AM$10,28,FALSE) -> 1 | F6: =VLOOKUP(B6,Calculations!$A$5:$AM$10,29,FALSE) -> 1 | G6: =VLOOKUP(B6,Calculations!$A$5:$AM$10,34,FALSE) -> 0.086556169 | H6: =VLOOKUP(B6,Calculations!$A$5:$AM$10,35,FALSE) -> 0.83844781 | I6: =VLOOKUP(B6,Calculations!$A$5:$AM$10,36,FALSE) -> 0.96768956 | J6: =VLOOKUP(B6,Calculations!$A$5:$AM$10,5,FALSE) -> TESTED | K6: =VLOOKUP(B6,Calculations!$A$5:$AM$10,39,FALSE) -> VALIDATED
A7: 2 | B7: P7 | C7: =VLOOKUP(B7,Calculations!$A$5:$AM$10,2,FALSE) -> FQPF7P20 | D7: =VLOOKUP(B7,Calculations!$A$5:$AM$10,3,FALSE) -> FQP3N80C | E7: =VLOOKUP(B7,Calculations!$A$5:$AM$10,28,FALSE) -> 1 | F7: =VLOOKUP(B7,Calculations!$A$5:$AM$10,29,FALSE) -> 0.99 | G7: =VLOOKUP(B7,Calculations!$A$5:$AM$10,34,FALSE) -> 0.086556169 | H7: =VLOOKUP(B7,Calculations!$A$5:$AM$10,35,FALSE) -> 0.83844781 | I7: =VLOOKUP(B7,Calculations!$A$5:$AM$10,36,FALSE) -> 0.95968956 | J7: =VLOOKUP(B7,Calculations!$A$5:$AM$10,5,FALSE) -> NOT TESTED | K7: =VLOOKUP(B7,Calculations!$A$5:$AM$10,39,FALSE) -> WAITING VALIDATION
A8: 3 | B8: P21 | C8: =VLOOKUP(B8,Calculations!$A$5:$AM$10,2,FALSE) -> IRFI9620GPBF | D8: =VLOOKUP(B8,Calculations!$A$5:$AM$10,3,FALSE) -> IRFI620GPBF | E8: =VLOOKUP(B8,Calculations!$A$5:$AM$10,28,FALSE) -> 0.98787879 | F8: =VLOOKUP(B8,Calculations!$A$5:$AM$10,29,FALSE) -> 0.8988701 | G8: =VLOOKUP(B8,Calculations!$A$5:$AM$10,34,FALSE) -> 0.30769231 | H8: =VLOOKUP(B8,Calculations!$A$5:$AM$10,35,FALSE) -> 0.81636555 | I8: =VLOOKUP(B8,Calculations!$A$5:$AM$10,36,FALSE) -> 0.88236919 | J8: =VLOOKUP(B8,Calculations!$A$5:$AM$10,5,FALSE) -> NOT TESTED | K8: =VLOOKUP(B8,Calculations!$A$5:$AM$10,39,FALSE) -> WAITING VALIDATION
A9: 4 | B9: P10 | C9: =VLOOKUP(B9,Calculations!$A$5:$AM$10,2,FALSE) -> FQPF7P20 | D9: =VLOOKUP(B9,Calculations!$A$5:$AM$10,3,FALSE) -> FQPF4N90C | E9: =VLOOKUP(B9,Calculations!$A$5:$AM$10,28,FALSE) -> 1 | F9: =VLOOKUP(B9,Calculations!$A$5:$AM$10,29,FALSE) -> 0.83950914 | G9: =VLOOKUP(B9,Calculations!$A$5:$AM$10,34,FALSE) -> 0.25423729 | H9: =VLOOKUP(B9,Calculations!$A$5:$AM$10,35,FALSE) -> 0.81073969 | I9: =VLOOKUP(B9,Calculations!$A$5:$AM$10,36,FALSE) -> 0.83375525 | J9: =VLOOKUP(B9,Calculations!$A$5:$AM$10,5,FALSE) -> TESTED | K9: =VLOOKUP(B9,Calculations!$A$5:$AM$10,39,FALSE) -> WAITING VALIDATION
A10: 5 | B10: P22 | C10: =VLOOKUP(B10,Calculations!$A$5:$AM$10,2,FALSE) -> IRFI9630GPBF | D10: =VLOOKUP(B10,Calculations!$A$5:$AM$10,3,FALSE) -> IRFI630GPBF | E10: =VLOOKUP(B10,Calculations!$A$5:$AM$10,28,FALSE) -> 0.8228592 | F10: =VLOOKUP(B10,Calculations!$A$5:$AM$10,29,FALSE) -> 0.62299715 | G10: =VLOOKUP(B10,Calculations!$A$5:$AM$10,34,FALSE) -> 0.14285714 | H10: =VLOOKUP(B10,Calculations!$A$5:$AM$10,35,FALSE) -> 0.81148888 | I10: =VLOOKUP(B10,Calculations!$A$5:$AM$10,36,FALSE) -> 0.6606955 | J10: =VLOOKUP(B10,Calculations!$A$5:$AM$10,5,FALSE) -> NOT TESTED | K10: =VLOOKUP(B10,Calculations!$A$5:$AM$10,39,FALSE) -> WAITING VALIDATION
A11: 6 | B11: P1 | C11: =VLOOKUP(B11,Calculations!$A$5:$AM$10,2,FALSE) -> FQP3P20 | D11: =VLOOKUP(B11,Calculations!$A$5:$AM$10,3,FALSE) -> FQP3N30 | E11: =VLOOKUP(B11,Calculations!$A$5:$AM$10,28,FALSE) -> 0.99 | F11: =VLOOKUP(B11,Calculations!$A$5:$AM$10,29,FALSE) -> 0.98583333 | G11: =VLOOKUP(B11,Calculations!$A$5:$AM$10,34,FALSE) -> 0.085714286 | H11: =VLOOKUP(B11,Calculations!$A$5:$AM$10,35,FALSE) -> 0.91154719 | I11: =VLOOKUP(B11,Calculations!$A$5:$AM$10,36,FALSE) -> 0.9709761 | J11: =VLOOKUP(B11,Calculations!$A$5:$AM$10,5,FALSE) -> TESTED | K11: =VLOOKUP(B11,Calculations!$A$5:$AM$10,39,FALSE) -> NOT VALIDATED
A12: Preferred current-build reference: P8 (FQPF7P20 / FQPF3N80C). P7 is electrically close but uses a non-insulated Q6 package. P21 has low absolute gate burden but a larger fixed-100 Ω pole mismatch. P1 remains a strong historical comparison only.
